Workbook

Sheet 갑지
B3: 내 역 서
B5: 공 사 명 : 부산역 맞이방 철도기념품(굿즈) 전문점 신축공사
B7: 공 사 비 (원) | C7: 공급가액
C8: 부가가치세
C9: 총 계
B10: 총 공 사 비 (원)
D13: 업체명 | E13: : | F13: (인)
D14: 대표이사 | E14: :
D15: 대표전화 | E15: :
D16: 이메일 | E16: :
C18: 코레일유통(주) 귀하

Sheet 원가계산서
B1: 공 사 원 가 계 산 서
B2: 공사명 : 부산역 맞이방 철도기념품(굿즈) 전문점 신축공사
B3: 비 목 | E3: 금 액 | F3: 구 성 비 | G3: 비 고
A4: A1 | B4: 순 공 사 원 가 | C4: 재 료 비 | D4: 직 접 재 료 비 | E4: =TRUNC(공종별집계표!F5, 0) -> 0
A5: A2 | D5: 간 접 재 료 비 | E5: 0
A6: A3 | D6: 작업설, 부산물(△) | E6: 0
A7: AS | D7: [ 소 계 ] | E7: =TRUNC(E4+E5-E6, 0) -> 0
A8: B1 | C8: 노 무 비 | D8: 직 접 노 무 비 | E8: =TRUNC(공종별집계표!H5, 0) -> 0
A9: B2 | D9: 간 접 노 무 비 | E9: =TRUNC(E8*0.175, 0) -> 0 | F9: 직접노무비 * 17.5%
A10: BS | D10: [ 소 계 ] | E10: =TRUNC(E8+E9, 0) -> 0
A11: C2 | C11: 경 비 | D11: 경 비 | E11: =TRUNC(공종별집계표!J5, 0) -> 0
A12: C4 | D12: 산 재 보 험 료 | E12: =TRUNC(E10*0.0356, 0) -> 0 | F12: 노무비 * 3.56%
A13: C5 | D13: 고 용 보 험 료 | E13: =TRUNC(E10*0.0101, 0) -> 0 | F13: 노무비 * 1.01%
A14: C6 | D14: 국민 건강 보험료 | E14: =TRUNC(E8*0.03595*0, 0) -> 0 | F14: 직접노무비 * 3.595% | G14: 1개월미만제외
A15: C7 | D15: 국민 연금 보험료 | E15: =TRUNC(E8*0.0475*0, 0) -> 0 | F15: 직접노무비 * 4.75% | G15: 1개월미만제외
A16: C8 | D16: 퇴직 공제 부금비 | E16: =TRUNC(E8*0.023, 0) -> 0 | F16: 직접노무비 * 2.3%
A17: CA | D17: 산업안전보건관리비 | E17: =TRUNC((E7+E8+(0/1.1))*0.0311, 0) -> 0 | F17: (재료비+직노+관급자재비) * 3.11%
A18: CB | D18: 노인장기요양보험료 | E18: =TRUNC(E14*0.1214*0, 0) -> 0 | F18: 건강보험료 * 13.14% | G18: 1개월미만제외
A19: CD | D19: 석면부담금 | E19: =TRUNC(E10*0.00006, 0) -> 0 | F19: 노무비 * 0.006%
A20: CC | D20: 임금채권부담금 | E20: =TRUNC(E10*0.0009, 0) -> 0 | F20: 노무비 * 0.09%
A21: CG | D21: 기 타 경 비 | E21: =TRUNC((E7+E10)*0.05, 0) -> 0 | F21: (재료비+노무비) * 5%
A22: CH | D22: 환 경 보 전 비 | E22: =TRUNC((E7+E8+E11)*0.003, 0) -> 0 | F22: (재료비+직노+경비) * 0.3%
A23: CS | D23: [ 소 계 ] | E23: =TRUNC(E11+E12+E13+E14+E15+E16+E17+E18+E20+E19+E21+E22, 0) -> 0
A24: S1 | B24: 계 | E24: =TRUNC(E7+E10+E23, 0) -> 0
A25: D1 | B25: 일 반 관 리 비 | E25: =TRUNC(E24*0.08, 0) -> 0 | F25: 계 * 8%
A26: D2 | B26: 이 윤 | E26: =TRUNC((E10+E23+E25)*0.15, 0) -> 0 | F26: (노무비+경비+일반관리비) * 15%
A27: D3 | B27: 폐기물처리비
A28: D4 | B28: 작업부산물(철거)
A29: D9 | B29: 공 급 가 액
A30: DB | B30: 부 가 가 치 세 | F30: 공급가액 * 10%
A31: DH | B31: 도 급 액
A32: S2 | B32: 총 공 사 비

Sheet 공종별집계표
A1: 공 종 별 집 계 표
A2: [ 부산역 맞이방 철도기념품(굿즈) 전문점 신축공사 ]
A3: 품 명 | B3: 규 격 | C3: 단위 | D3: 수량 | E3: 재 료 비 | G3: 노 무 비 | I3: 경 비 | K3: 합 계 | M3: 비 고 | N3: 공종코드 | O3: 변수 | P3: 상위공종 | Q3: 공종구분 | R3: 공종레벨 | S3: 공종소계 | T3: 원가계산서 연결금액
E4: 단 가 | F4: 금 액 | G4: 단 가 | H4: 금 액 | I4: 단 가 | J4: 금 액 | K4: 단 가 | L4: 금 액
A5: 부산역 맞이방 철도기념품(굿즈) 전문점 신축공사 | D5: 1 | E5: =F6 -> 0 | F5: =E5*D5 -> 0 | G5: =H6 -> 0 | H5: =G5*D5 -> 0 | I5: =J6 -> 0 | J5: =I5*D5 -> 0 | K5: =E5+G5+I5 -> 0 | L5: =F5+H5+J5 -> 0 | N5: 01 | R5: 1
A6: 01.전문점공사 | D6: 1 | E6: =F7+F8+F9+F10+F11+F12+F13+F14+F15+F16+F17 -> 0 | F6: =E6*D6 -> 0 | G6: =H7+H8+H9+H10+H11+H12+H13+H14+H15+H16+H17 -> 0 | H6: =G6*D6 -> 0 | I6: =J7+J8+J9+J10+J11+J12+J13+J14+J15+J16+J17 -> 0 | J6: =I6*D6 -> 0 | K6: =E6+G6+I6 -> 0 | L6: =F6+H6+J6 -> 0 | N6: 0101 | P6: 01 | R6: 2
A7: 0101 가 설 공 사 | D7: 1 | E7: =공종별내역서!F27 -> 0 | F7: =E7*D7 -> 0 | G7: =공종별내역서!H27 -> 0 | H7: =G7*D7 -> 0 | I7: =공종별내역서!J27 -> 0 | J7: =I7*D7 -> 0 | K7: =E7+G7+I7 -> 0 | L7: =F7+H7+J7 -> 0 | N7: 010101 | P7: 0101 | R7: 3
A8: 0102 타 일 공 사 | D8: 1 | E8: =공종별내역서!F51 -> 0 | F8: =E8*D8 -> 0 | G8: =공종별내역서!H51 -> 0 | H8: =G8*D8 -> 0 | I8: =공종별내역서!J51 -> 0 | J8: =I8*D8 -> 0 | K8: =E8+G8+I8 -> 0 | L8: =F8+H8+J8 -> 0 | N8: 010102 | P8: 0101 | R8: 3
A9: 0103 목공사및수장공사 | D9: 1 | E9: =공종별내역서!F85 -> 0 | F9: =E9*D9 -> 0 | G9: =공종별내역서!H85 -> 0 | H9: =G9*D9 -> 0 | I9: =공종별내역서!J85 -> 0 | J9: =I9*D9 -> 0 | K9: =E9+G9+I9 -> 0 | L9: =F9+H9+J9 -> 0 | N9: 010103 | P9: 0101 | R9: 3
A10: 0104 금 속 공 사 | D10: 1 | E10: =공종별내역서!F109 -> 0 | F10: =E10*D10 -> 0 | G10: =공종별내역서!H109 -> 0 | H10: =G10*D10 -> 0 | I10: =공종별내역서!J109 -> 0 | J10: =I10*D10 -> 0 | K10: =E10+G10+I10 -> 0 | L10: =F10+H10+J10 -> 0 | N10: 010104 | P10: 0101 | R10: 3
A11: 0105 창호 및 유리공사 | D11: 1 | E11: =공종별내역서!F133 -> 0 | F11: =E11*D11 -> 0 | G11: =공종별내역서!H133 -> 0 | H11: =G11*D11 -> 0 | I11: =공종별내역서!J133 -> 0 | J11: =I11*D11 -> 0 | K11: =E11+G11+I11 -> 0 | L11: =F11+H11+J11 -> 0 | N11: 010105 | P11: 0101 | R11: 3
A12: 0106 칠 공 사 | D12: 1 | E12: =공종별내역서!F157 -> 0 | F12: =E12*D12 -> 0 | G12: =공종별내역서!H157 -> 0 | H12: =G12*D12 -> 0 | I12: =공종별내역서!J157 -> 0 | J12: =I12*D12 -> 0 | K12: =E12+G12+I12 -> 0 | L12: =F12+H12+J12 -> 0 | N12: 010106 | P12: 0101 | R12: 3
A13: 0107 철 거 공 사 | D13: 1 | E13: =공종별내역서!F181 -> 0 | F13: =E13*D13 -> 0 | G13: =공종별내역서!H181 -> 0 | H13: =G13*D13 -> 0 | I13: =공종별내역서!J181 -> 0 | J13: =I13*D13 -> 0 | K13: =E13+G13+I13 -> 0 | L13: =F13+H13+J13 -> 0 | N13: 010107 | P13: 0101 | R13: 3
A14: 0108 가 구 공 사 | D14: 1 | E14: =공종별내역서!F230 -> 0 | F14: =E14*D14 -> 0 | G14: =공종별내역서!H230 -> 0 | H14: =G14*D14 -> 0 | I14: =공종별내역서!J230 -> 0 | J14: =I14*D14 -> 0 | K14: =E14+G14+I14 -> 0 | L14: =F14+H14+J14 -> 0 | N14: 010108 | P14: 0101 | R14: 3
A15: 0109 사 인 공 사 | D15: 1 | E15: =공종별내역서!F263 -> 0 | F15: =E15*D15 -> 0 | G15: =공종별내역서!H263 -> 0 | H15: =G15*D15 -> 0 | I15: =공종별내역서!J263 -> 0 | J15: =I15*D15 -> 0 | K15: =E15+G15+I15 -> 0 | L15: =F15+H15+J15 -> 0 | N15: 010109 | P15: 0101 | R15: 3
A16: 0110 냉 난 방 공사 | D16: 1 | E16: =공종별내역서!F287 -> 0 | F16: =E16*D16 -> 0 | G16: =공종별내역서!H287 -> 0 | H16: =G16*D16 -> 0 | I16: =공종별내역서!J287 -> 0 | J16: =I16*D16 -> 0 | K16: =E16+G16+I16 -> 0 | L16: =F16+H16+J16 -> 0 | N16: 010110 | P16: 0101 | R16: 3
A17: 0111 골 재 비 | D17: 1 | E17: =공종별내역서!F311 -> 0 | F17: =E17*D17 -> 0 | G17: =공종별내역서!H311 -> 0 | H17: =G17*D17 -> 0 | I17: =공종별내역서!J311 -> 0 | J17: =I17*D17 -> 0 | K17: =E17+G17+I17 -> 0 | L17: =F17+H17+J17 -> 0 | N17: 010111 | P17: 0101 | R17: 3
A18: 0112 건설폐기물처리비 | D18: 1 | E18: =공종별내역서!F335 -> 0 | F18: =E18*D18 -> 0 | G18: =공종별내역서!H335 -> 0 | H18: =G18*D18 -> 0 | I18: =공종별내역서!J335 -> 0 | J18: =I18*D18 -> 0 | K18: =E18+G18+I18 -> 0 | L18: =F18+H18+J18 -> 0 | N18: 010112 | Q18: 6 | R18: 3 | T18: =L18*1 -> 0
A19: 0113 작업부산물(철거) | D19: 1 | E19: =공종별내역서!F359 -> 0 | F19: =E19*D19 -> 0 | G19: =공종별내역서!H359 -> 0 | H19: =G19*D19 -> 0 | I19: =공종별내역서!J359 -> 0 | J19: =I19*D19 -> 0 | K19: =E19+G19+I19 -> 0 | L19: =F19+H19+J19 -> 0 | N19: 010113 | Q19: 1 | R19: 3 | T19: =L19*1 -> 0
A27: [ 합 계 ] | F27: =F5 -> 0 | H27: =H5 -> 0 | J27: =J5 -> 0 | L27: =L5 -> 0

Sheet 공종별내역서
A1: [ 부산역 맞이방 철도기념품(굿즈) 전문점 신축공사 ]
A2: 품 명 | B2: 규 격 | C2: 단위 | D2: 수량 | E2: 재 료 비 | G2: 노 무 비 | I2: 경 비 | K2: 합 계 | M2: 비 고 | N2: 품목코드 | O2: 변수 | P2: 설정 | Q2: 공종코드 | R2: 일위 | S2: 단산 | T2: 자재 | U2: 손료적용 | V2: 손료저장 | W2: 적용율 | X2: JUK1 | Y2: JUK2 | Z2: JUK3 | AA2: JUK4 | AB2: JUK5 | AC2: JUK6 | AD2: JUK7 | AE2: JUK8 | AF2: JUK9 | AG2: JUK10 | AH2: JUK11 | AI2: JUK12 | AJ2: JUK13 | AK2: JUK14 | AL2: JUK15 | AM2: JUK16 | AN2: JUK17 | AO2: JUK18 | AP2: JUK19 | AQ2: JUK20 | AR2: 자재구분 | AS2: 공종구분 | AT2: 공종레벨 | AU2: 공종+자재 | AV2: 고유번호
E3: 단 가 | F3: 금 액 | G3: 단 가 | H3: 금 액 | I3: 단 가 | J3: 금 액 | K3: 단 가 | L3: 금 액
A4: 0101 가 설 공 사 | Q4: 010101
A5: 강관 조립말비계(이동식)설치 및 해체 | B5: 높이 2m, 3개월 | C5: 대 | D5: 1 | M5: 호표 1 | N5: 45334A8760D7DF4C230CDB471B89C | Q5: 010101 | R5: T | S5: F | T5: F | AU5: 01010145334A8760D7DF4C230CDB471B89C | AV5: 64
A6: 강관 조립말비계(이동식)설치 및 해체 | B6: 높이 4m, 3개월 | C6: 대 | D6: 1 | M6: 호표 2 | N6: 45334A8760D7DF4C230CDB7C65F07 | Q6: 010101 | R6: T | S6: F | T6: F | AU6: 01010145334A8760D7DF4C230CDB7C65F07 | AV6: 63
A7: 건축물 현장정리 | B7: 개보수 | C7: M2 | D7: 33 | M7: 호표 3 | N7: 45334A8268DE974FF602247D5722F | Q7: 010101 | R7: T | S7: F | T7: F | AU7: 01010145334A8268DE974FF602247D5722F | AV7: 6
A8: 먹매김 | B8: 개보수 | C8: M2 | D8: 33 | M8: 호표 4 | N8: 45334A8268DE974FF602247D5722D | Q8: 010101 | R8: T | S8: F | T8: F | AU8: 01010145334A8268DE974FF602247D5722D | AV8: 8
A9: 준공청소 | C9: M2 | D9: 33 | M9: 호표 5 | N9: 45334A826886FB4CC701DC8FE8581 | Q9: 010101 | R9: T | S9: F | T9: F | AU9: 01010145334A826886FB4CC701DC8FE8581 | AV9: 65
A10: 공사용가설판넬 설치 | B10: (야간)난연2등급 50t(도어문짝포함/하드웨어별도) | C10: M2 | D10: 98 | M10: 호표 6 | N10: 45334A8760F2C74D2C0FA0FF543ADC7 | Q10: 010101 | R10: T | S10: F | T10: F | AU10: 01010145334A8760F2C74D2C0FA0FF543ADC7 | AV10: 68
A11: 공사용가설판넬 해체 | B11: (야간)난연2등급 50t(도어문짝포함/하드웨어별도) | C11: M2 | D11: 98 | M11: 호표 7 | N11: 45334A8760F2C74D2C0FA0FF543AA | Q11: 010101 | R11: T | S11: F | T11: F | AU11: 01010145334A8760F2C74D2C0FA0FF543AA | AV11: 67
A12: 공사용가설칸막이도아 설치 | B12: (야간)양개형,하드웨어및디지털도어록포함 | C12: EA | D12: 1 | M12: 호표 8 | N12: 45334A8268EF6F4886038285B4E6B | Q12: 010101 | R12: T | S12: F | T12: F | AU12: 01010145334A8268EF6F4886038285B4E6B | AV12: 66
A13: 코너범퍼설치 | B13: (야간) | C13: EA | D13: 4 | M13: 호표 9 | N13: 45334A8268EF6F4886038285B4E1F | Q13: 010101 | R13: T | S13: F | T13: F | AU13: 01010145334A8268EF6F4886038285B4E1F | AV13: 83
A14: 바닥보양 | B14: (야간)플라베니아+테이프 | C14: M2 | D14: 30 | M14: 호표 10 | N14: 45334A8268EF6F488400E89D8939C | Q14: 010101 | R14: T | S14: F | T14: F | AU14: 01010145334A8268EF6F488400E89D8939C | AV14: 78
A15: 상부방진막 설치 및 해체 | B15: 방진망, P.E, 1.5*150m | C15: M2 | D15: 11 | M15: 호표 11 | N15: 45334A8760C5E2485907A49124064 | Q15: 010101 | R15: T | S15: F | T15: F | AU15: 01010145334A8760C5E2485907A49124064 | AV15: 220
A16: 공사안내판 설치 | B16: 800*1100 | C16: EA | D16: 1 | M16: 견적서 | N16: 448D40AF6244244C8D08890AB337E193FD90E | Q16: 010101 | R16: F | S16: F | T16: T | AU16: 010101448D40AF6244244C8D08890AB337E193FD90E | AV16: 69
A17: 공사현수막 설치 | B17: 3000*600 | C17: EA | D17: 1 | M17: 견적서 | N17: 448D40AF6244244C8D08890AB337E193FD90D | Q17: 010101 | R17: F | S17: F | T17: T | AU17: 010101448D40AF6244244C8D08890AB337E193FD90D | AV17: 70
Q18: 010101
Q19: 010101
Q20: 010101
Q21: 010101
Q22: 010101
Q23: 010101
Q24: 010101
Q25: 010101
Q26: 010101
A27: [ 합 계 ] | F27: =SUMIF(Q5:Q26,"010101",F5:F26) -> 0 | H27: =SUMIF(Q5:Q26,"010101",H5:H26) -> 0 | J27: =SUMIF(Q5:Q26,"010101",J5:J26) -> 0 | L27: =SUMIF(Q5:Q26,"010101",L5:L26) -> 0 | N27: TOTAL
A28: 0102 타 일 공 사 | Q28: 010102
A29: 포세린타일[구입량] | B29: 바닥, 600*600*10mm | C29: M2 | D29: 33.12 | M29: 견적서 | N29: 44334F11659DA1420A0E576AA3B636C91CF16 | Q29: 010102 | R29: F | S29: F | T29: T | AU29: 01010244334F11659DA1420A0E576AA3B636C91CF16 | AV29: 97
A30: 포세린타일 압착 붙이기(바탕 10mm+압 5mm) | B30: 바닥, 600*600(일반C, 백색줄눈) | C30: M2 | D30: 30 | M30: 호표 12 | N30: 4533466A62336C47D602D68E65105 | Q30: 010102 | R30: T | S30: F | T30: F | AU30: 0101024533466A62336C47D602D68E65105 | AV30: 96
Q31: 010102
Q32: 010102
Q33: 010102
Q34: 010102
Q35: 010102
Q36: 010102
Q37: 010102
Q38: 010102
Q39: 010102
Q40: 010102
...
