Workbook
Name ____gh1: #N/A
Name ___gh1: #N/A
Name __gh1: '총괄표 '!__gh1
Name __gh1: #N/A
Name __K1: #REF!
Name __K3: #REF!
Name __K6: #REF!
Name __p2: #REF!
Name __P22: #REF!
Name __P31: #REF!
Name __P33: #REF!
Name _10_____________________________________________________________________________________________________________________________________________________________________________\SM: '[2]#REF'!#REF!
Name _100____________________________________________________________________________________________________________________________________________________________________________ME: '[2]#REF'!#REF!
Name _100_________________________________________________________________________________________________________________________________________________________________________\LA: '[2]#REF'!#REF!
Name _1002_________________________________________________________________________0\SM: '[4]#REF'!#REF!
Name _1004_____________________________________________________________________________________________________________________________________________________3__Crite: #REF!
Name _1006_____________________________________________________________________________________________________________________________________________________3__Criteria: #REF!
Name _1006_______________________________________________________________________3__Crite: #REF!
Name _1007_______________________________________________________________________3__Criteria: #REF!
Name _1008_______________________________________________________________________G_0Extract: #REF!
Name _1009_______________________________________________________________________G__Extr: #REF!
Name _101_________________________________________________________________________________________________________________________________________________________________________\MID: '[2]#REF'!#REF!
Name _1010_______________________________________________________________________G__Extract: #REF!
Name _1011__________________________________________________________________________ME: '[2]#REF'!#REF!
Name _1012_____________________________________________________________________________________________________________________________________________________G_0Extract: #REF!
Name _1012__________________________________________________________________________ME: '[2]#REF'!#REF!
Name _1014_____________________________________________________________________________________________________________________________________________________G__Extr: #REF!
Name _1016_____________________________________________________________________________________________________________________________________________________G__Extract: #REF!
Name _1018________________________________________________________________________________________________________________________________________________________ME: '[2]#REF'!#REF!
Name _1019______________________________________________________________________\LA: '[2]#REF'!#REF!
Name _102_________________________________________________________________________________________________________________________________________________________________________\SM: '[2]#REF'!#REF!
Name _1020________________________________________________________________________________________________________________________________________________________ME: '[2]#REF'!#REF!
Name _1020_________________________________________________________________________________________________________________________________\LA: '[2]#REF'!#REF!
Name _1020______________________________________________________________________\MID: '[2]#REF'!#REF!
Name _1021_________________________________________________________________________________________________________________________________\MID: '[2]#REF'!#REF!
Name _1021______________________________________________________________________\SM: '[2]#REF'!#REF!
Name _1022_________________________________________________________________________________________________________________________________\SM: '[2]#REF'!#REF!
Name _1025_____________________________________________________________________0\SM: '[4]#REF'!#REF!
Name _1026________________________________________________________________________________________________________________________________0\SM: '[4]#REF'!#REF!
Name _1028_______________________________________________________________________________________________________________________________________________________\LA: '[2]#REF'!#REF!
Name _1029___________________________________________________________________3__Crite: #REF!
Name _1030_______________________________________________________________________________________________________________________________________________________\MID: '[2]#REF'!#REF!
Name _1030___________________________________________________________________3__Criteria: #REF!
Name _1031______________________________________________________________________________________________________________________________3__Crite: #REF!
Name _1031___________________________________________________________________G_0Extract: #REF!
Name _1032_______________________________________________________________________________________________________________________________________________________\SM: '[2]#REF'!#REF!
Name _1032______________________________________________________________________________________________________________________________3__Criteria: #REF!
Name _1032___________________________________________________________________G__Extr: #REF!
Name _1033___________________________________________________________________G__Extract: #REF!
Name _1034______________________________________________________________________ME: '[2]#REF'!#REF!
Name _1035______________________________________________________________________________________________________________________________G_0Extract: #REF!
Name _1035______________________________________________________________________ME: '[2]#REF'!#REF!
Name _1036______________________________________________________________________________________________________________________________G__Extr: #REF!
Name _1037______________________________________________________________________________________________________________________________G__Extract: #REF!
Name _1038_________________________________________________________________________________________________________________________________ME: '[2]#REF'!#REF!
Name _1039_________________________________________________________________________________________________________________________________ME: '[2]#REF'!#REF!
Name _1040______________________________________________________________________________________________________________________________________________________0\SM: '[4]#REF'!#REF!
Name _1042__________________________________________________________________\LA: '[2]#REF'!#REF!
Name _1043__________________________________________________________________\MID: '[2]#REF'!#REF!
Name _1044__________________________________________________________________\SM: '[2]#REF'!#REF!

Sheet 표지
C3: 2018년 12월
C6: 건 명 : [ 부산역 회의실 및 전문점 신축공사 ]
B8: 건 축 공 사 내 역 서
B23: 코레일유통(주)
C27: 2018년 12월
C30: 건 명 : [ 부산역 회의실 및 전문점 신축공사 ]
B32: 일위대가, 단가대비표, 수량산출서
B47: 코레일유통(주)

Sheet 원가계산서
B1: 공 사 원 가 계 산 서
B2: 건 명 : [ 부산역 회의실 및 전문점 신축공사 ]
B3: 비 목 | E3: 금 액 | F3: 구 성 비 | G3: 비 고
A4: A1 | B4: 순 공 사 원 가 | C4: 재 료 비 | D4: 직 접 재 료 비 | E4: ='총괄표 '!E13-E5 -> 0 | I4: 재료비합계 | J4: =E4+E5 -> 0
A5: A2 | D5: 간 접 재 료 비 | E5: =공종별집계표!E7+공종별집계표!E17+공종별집계표!E27+공종별집계표!E36 -> 0 | F5: 가설공사 재료비 | I5: 가설공사
A6: A3 | D6: 작업설, 부산물(△) | E6: ='총괄표 '!K23 -> 0
A7: AS | D7: [ 소 계 ] | E7: =E4+E5-E6 -> 0
A8: B1 | C8: 노 무 비 | D8: 직 접 노 무 비 | E8: ='총괄표 '!G13 -> 0
A9: B2 | D9: 간 접 노 무 비 | E9: =TRUNC(E8*0.079, 0) -> 0 | F9: 직접노무비 * 7.9% | H9: 2018년6월부터 적용(코레일유통) | J9: =E4+E5+E8+E11 -> 0
A10: BS | D10: [ 소 계 ] | E10: =TRUNC(E8+E9, 0) -> 0
A11: C2 | C11: 경 비 | D11: 기 계 경 비 | E11: ='총괄표 '!I13 -> 0
A12: C4 | D12: 산 재 보 험 료 | E12: =TRUNC(E10*0.0405, 0) -> 0 | F12: 노무비 * 4.05% | G12: 모든공사에적용 | H12: 2018년 하반기 변경
A13: C5 | D13: 고 용 보 험 료 | E13: =TRUNC(E10*0.0087, 0) -> 0 | F13: 노무비 * 0.87% | G13: 모든공사에적용
A14: C6 | D14: 국민 건강 보험료 | E14: =E8*3.12% -> 0 | F14: 직접노무비 * 3.12% | G14: 1개월이상
A15: C7 | D15: 국민 연금 보험료 | E15: =E8*4.5% -> 0 | F15: 직접노무비 * 4.5% | G15: 1개월이상
A16: CB | D16: 노인장기요양보험료 | E16: =TRUNC(E14*0.0738, 0) -> 0 | F16: 건강보험료 * 7.38% | G16: 1개월이상 | H16: 2018년 하반기 변경
A17: C8 | D17: 퇴직 공제 부금비 | F17: 직접노무비 * 2.3% | G17: 3억원이상(본공사제외)
A18: CA | D18: 산업안전보건관리비 | E18: =TRUNC(E7+E8)*0.0293 -> 0 | F18: (재료비+직노+관급자재) * 2.93% | G18: 4천만원이상
A19: CH | D19: 환 경 보 전 비 | E19: =TRUNC((E7+E8+E11)*0.005, 0) -> 0 | F19: (재료비+직노+기계경비) * 0.5%
A20: CG | D20: 기 타 경 비 | E20: =TRUNC((E7+E10)*0.055, 0) -> 0 | F20: (재료비+노무비) * 5.5% | H20: 2018년4월5일 적용(코레일유통)
A21: CS | D21: [ 소 계 ] | E21: =TRUNC(E11+E12+E13+E14+E15+E17+E18+E16+E20+E19, 0) -> 0
A22: S1 | B22: 계 | E22: =TRUNC(E7+E10+E21, 0) -> 0
A23: D1 | B23: 일 반 관 리 비 | E23: =TRUNC(E22*0.06, 0) -> 0 | F23: 계 * 6%
A24: D2 | B24: 이 윤 | E24: =TRUNC((E10+E21+E23)*0.15) -> 0 | F24: (노무비+경비+일반관리비) * 15%
A25: D9 | B25: 공 급 가 액 | E25: =TRUNC((E22+E23+E24), 0) -> 0
A26: DB | B26: 부 가 가 치 세 | F26: 공급가액 * 10%
A27: DH | B27: 도 급 액 | G27: 천원 단위절사
A28: S2 | B28: 총 공 사 비

Sheet 총괄표 
A1: 총 괄 표
A2: [ 부산역 회의실 및 전문점 신축공사 ]
A3: 품 명 | B3: 단위 | C3: 수량 | D3: 재 료 비 | F3: 노 무 비 | H3: 경 비 | J3: 합 계 | L3: 비고
D4: 단가 | E4: 금액 | F4: 단가 | G4: 금액 | H4: 단가 | I4: 금액 | J4: 단가 | K4: 금액
A5: ■ 총 괄 표
A6: 01 ▶회 의 실-1 | B6: 식 | C6: 1 | E6: =공종별집계표!F6 -> 0 | G6: =공종별집계표!H6 -> 0 | I6: =공종별집계표!J6 -> 0 | K6: =E6+G6+I6 -> 0
A7: 02 ▶회 의 실-2 | B7: 식 | C7: 1 | E7: =공종별집계표!F16 -> 0 | G7: =공종별집계표!H16 -> 0 | I7: =공종별집계표!J16 -> 0 | K7: =E7+G7+I7 -> 0
A8: 03 ▶전 문 점-1 | B8: 식 | C8: 1 | E8: =공종별집계표!F26 -> 0 | G8: =공종별집계표!H26 -> 0 | I8: =공종별집계표!J26 -> 0 | K8: =E8+G8+I8 -> 0
A9: 04 ▶전 문 점-2 | B9: 식 | C9: 1 | E9: =공종별집계표!F35 -> 0 | G9: =공종별집계표!H35 -> 0 | I9: =공종별집계표!J35 -> 0 | K9: =E9+G9+I9 -> 0
A13: <소 계> | E13: =SUM(E6:E12) -> 0 | G13: =SUM(G6:G12) -> 0 | I13: =SUM(I6:I12) -> 0 | K13: =SUM(K6:K12) -> 0
K14: =E14+G14+I14 -> 0
A15: <작업부산물> | K15: =E15+G15+I15 -> 0
A16: 01 ▶회 의 실-1 | B16: 식 | C16: 1 | E16: =공종별집계표!F15 -> 0 | G16: =공종별집계표!H15 -> 0 | I16: =공종별집계표!J15 -> 0 | K16: =E16+G16+I16 -> 0
A17: 02 ▶회 의 실-2 | B17: 식 | C17: 1 | E17: =공종별집계표!F25 -> 0 | G17: =공종별집계표!H25 -> 0 | I17: =공종별집계표!J25 -> 0 | K17: =E17+G17+I17 -> 0
A18: 03 ▶전 문 점-1 | B18: 식 | C18: 1 | E18: =공종별집계표!F34 -> 0 | G18: =공종별집계표!H34 -> 0 | I18: =공종별집계표!J34 -> 0 | K18: =E18+G18+I18 -> 0
A19: 04 ▶전 문 점-2 | B19: 식 | C19: 1 | E19: =공종별집계표!F43 -> 0 | G19: =공종별집계표!H43 -> 0 | I19: =공종별집계표!J43 -> 0 | K19: =E19+G19+I19 -> 0
A23: <소 계> | E23: =SUM(E16:E22) -> 0 | G23: =SUM(G16:G22) -> 0 | I23: =SUM(I16:I22) -> 0 | K23: =SUM(K16:K22) -> 0
A30: <소 계> | E30: =SUM(E25:E29) -> 0 | G30: =SUM(G25:G29) -> 0 | I30: =SUM(I25:I29) -> 0 | K30: =SUM(K25:K29) -> 0
K31: =E31+G31+I31 -> 0
A37: <소 계> | E37: =SUM(E33:E36) -> 0 | G37: =SUM(G33:G36) -> 0 | I37: =SUM(I33:I36) -> 0 | K37: =SUM(K33:K36) -> 0
A39: 마지막열은 지우지 마시오

Sheet 공종별집계표
A1: 공 종 별 집 계 표
A2: [ 부산역 회의실 및 전문점 신축공사 ]
A3: 품 명 | B3: 규 격 | C3: 단위 | D3: 수량 | E3: 재 료 비 | G3: 노 무 비 | I3: 경 비 | K3: 합 계 | M3: 비 고 | N3: 공종코드 | O3: 변수 | P3: 상위공종 | Q3: 공종구분 | R3: 공종레벨 | S3: 공종소계 | T3: 원가계산서 연결금액
E4: 단 가 | F4: 금 액 | G4: 단 가 | H4: 금 액 | I4: 단 가 | J4: 금 액 | K4: 단 가 | L4: 금 액
A5: 01 부산역 회의실 및 전문점 신축공사 | D5: 1 | E5: =F6+F16+F26+F35 -> 0 | F5: =E5*D5 -> 0 | G5: =H6+H16+H26+H35 -> 0 | H5: =G5*D5 -> 0 | I5: =J6+J16+J26+J35 -> 0 | J5: =I5*D5 -> 0 | K5: =E5+G5+I5 -> 0 | L5: =F5+H5+J5 -> 0 | N5: 01 | R5: 1 | S5: 1
A6: 0101 ■ 회 의 실-1 | D6: 1 | E6: =F7+F8+F9+F10+F11+F12+F13+F14 -> 0 | F6: =E6*D6 -> 0 | G6: =H7+H8+H9+H10+H11+H12+H13+H14 -> 0 | H6: =G6*D6 -> 0 | I6: =J7+J8+J9+J10+J11+J12+J13+J14 -> 0 | J6: =I6*D6 -> 0 | K6: =E6+G6+I6 -> 0 | L6: =F6+H6+J6 -> 0 | N6: 0101 | P6: 01 | R6: 2
A7: 010101 가 설 공 사 | D7: 1 | E7: =공종별내역서!F27 -> 0 | F7: =E7*D7 -> 0 | G7: =공종별내역서!H27 -> 0 | H7: =G7*D7 -> 0 | I7: =공종별내역서!J27 -> 0 | J7: =I7*D7 -> 0 | K7: =E7+G7+I7 -> 0 | L7: =F7+H7+J7 -> 0 | N7: 010101 | P7: 0101 | R7: 3
A8: 010102 철 거 공 사 | D8: 1 | E8: =공종별내역서!F51 -> 0 | F8: =E8*D8 -> 0 | G8: =공종별내역서!H51 -> 0 | H8: =G8*D8 -> 0 | I8: =공종별내역서!J51 -> 0 | J8: =I8*D8 -> 0 | K8: =E8+G8+I8 -> 0 | L8: =F8+H8+J8 -> 0 | N8: 010102 | P8: 0101 | R8: 3
A9: 010103 수 장 공 사 | D9: 1 | E9: =공종별내역서!F74 -> 0 | F9: =E9*D9 -> 0 | G9: =공종별내역서!H74 -> 0 | H9: =G9*D9 -> 0 | I9: =공종별내역서!J74 -> 0 | J9: =I9*D9 -> 0 | K9: =E9+G9+I9 -> 0 | L9: =F9+H9+J9 -> 0 | N9: 010103 | P9: 0101 | R9: 3
A10: 010104 금 속 공 사 | D10: 1 | E10: =공종별내역서!F98 -> 0 | F10: =E10*D10 -> 0 | G10: =공종별내역서!H98 -> 0 | H10: =G10*D10 -> 0 | I10: =공종별내역서!J98 -> 0 | J10: =I10*D10 -> 0 | K10: =E10+G10+I10 -> 0 | L10: =F10+H10+J10 -> 0 | N10: 010104 | P10: 0101 | R10: 3
A11: 010105 도 장 공 사 | D11: 1 | E11: =공종별내역서!F122 -> 0 | F11: =E11*D11 -> 0 | G11: =공종별내역서!H122 -> 0 | H11: =G11*D11 -> 0 | I11: =공종별내역서!J122 -> 0 | J11: =I11*D11 -> 0 | K11: =E11+G11+I11 -> 0 | L11: =F11+H11+J11 -> 0 | N11: 010105 | P11: 0101 | R11: 3
A12: 010106 창 호 공 사 | D12: 1 | E12: =공종별내역서!F146 -> 0 | F12: =E12*D12 -> 0 | G12: =공종별내역서!H146 -> 0 | H12: =G12*D12 -> 0 | I12: =공종별내역서!J146 -> 0 | J12: =I12*D12 -> 0 | K12: =E12+G12+I12 -> 0 | L12: =F12+H12+J12 -> 0 | N12: 010106 | P12: 0101 | R12: 3
A13: 010107 유 리 공 사 | D13: 1 | E13: =공종별내역서!F170 -> 0 | F13: =E13*D13 -> 0 | G13: =공종별내역서!H170 -> 0 | H13: =G13*D13 -> 0 | I13: =공종별내역서!J170 -> 0 | J13: =I13*D13 -> 0 | K13: =E13+G13+I13 -> 0 | L13: =F13+H13+J13 -> 0 | N13: 010107 | P13: 0101 | R13: 3
A14: 010108 에어컨 공사 | D14: 1 | E14: =공종별내역서!F194 -> 0 | F14: =E14*D14 -> 0 | G14: =공종별내역서!H194 -> 0 | H14: =G14*D14 -> 0 | I14: =공종별내역서!J194 -> 0 | J14: =I14*D14 -> 0 | K14: =E14+G14+I14 -> 0 | L14: =F14+H14+J14 -> 0 | N14: 010108 | P14: 0101 | R14: 3
A15: 010110 작업부산물(합계미포함) | D15: 1 | E15: =공종별내역서!F218 -> 0 | F15: =E15*D15 -> 0 | G15: =공종별내역서!H218 -> 0 | H15: =G15*D15 -> 0 | I15: =공종별내역서!J218 -> 0 | J15: =I15*D15 -> 0 | K15: =E15+G15+I15 -> 0 | L15: =F15+H15+J15 -> 0 | N15: 010110 | Q15: 1 | R15: 3 | T15: =L15*1 -> 0
A16: 0102 ■ 회 의 실-2 | D16: 1 | E16: =F17+F18+F19+F20+F21+F22+F23+F24 -> 0 | F16: =E16*D16 -> 0 | G16: =H17+H18+H19+H20+H21+H22+H23+H24 -> 0 | H16: =G16*D16 -> 0 | I16: =J17+J18+J19+J20+J21+J22+J23+J24 -> 0 | J16: =I16*D16 -> 0 | K16: =E16+G16+I16 -> 0 | L16: =F16+H16+J16 -> 0 | N16: 0102 | P16: 01 | R16: 2
A17: 010201 가 설 공 사 | D17: 1 | E17: =공종별내역서!F242 -> 0 | F17: =E17*D17 -> 0 | G17: =공종별내역서!H242 -> 0 | H17: =G17*D17 -> 0 | I17: =공종별내역서!J242 -> 0 | J17: =I17*D17 -> 0 | K17: =E17+G17+I17 -> 0 | L17: =F17+H17+J17 -> 0 | N17: 010201 | P17: 0102 | R17: 3
A18: 010202 철 거 공 사 | D18: 1 | E18: =공종별내역서!F266 -> 0 | F18: =E18*D18 -> 0 | G18: =공종별내역서!H266 -> 0 | H18: =G18*D18 -> 0 | I18: =공종별내역서!J266 -> 0 | J18: =I18*D18 -> 0 | K18: =E18+G18+I18 -> 0 | L18: =F18+H18+J18 -> 0 | N18: 010202 | P18: 0102 | R18: 3
A19: 010203 수 장 공 사 | D19: 1 | E19: =공종별내역서!F290 -> 0 | F19: =E19*D19 -> 0 | G19: =공종별내역서!H290 -> 0 | H19: =G19*D19 -> 0 | I19: =공종별내역서!J290 -> 0 | J19: =I19*D19 -> 0 | K19: =E19+G19+I19 -> 0 | L19: =F19+H19+J19 -> 0 | N19: 010203 | P19: 0102 | R19: 3
A20: 010204 금 속 공 사 | D20: 1 | E20: =공종별내역서!F314 -> 0 | F20: =E20*D20 -> 0 | G20: =공종별내역서!H314 -> 0 | H20: =G20*D20 -> 0 | I20: =공종별내역서!J314 -> 0 | J20: =I20*D20 -> 0 | K20: =E20+G20+I20 -> 0 | L20: =F20+H20+J20 -> 0 | N20: 010204 | P20: 0102 | R20: 3
A21: 010205 도 장 공 사 | D21: 1 | E21: =공종별내역서!F338 -> 0 | F21: =E21*D21 -> 0 | G21: =공종별내역서!H338 -> 0 | H21: =G21*D21 -> 0 | I21: =공종별내역서!J338 -> 0 | J21: =I21*D21 -> 0 | K21: =E21+G21+I21 -> 0 | L21: =F21+H21+J21 -> 0 | N21: 010205 | P21: 0102 | R21: 3
A22: 010206 창 호 공 사 | D22: 1 | E22: =공종별내역서!F362 -> 0 | F22: =E22*D22 -> 0 | G22: =공종별내역서!H362 -> 0 | H22: =G22*D22 -> 0 | I22: =공종별내역서!J362 -> 0 | J22: =I22*D22 -> 0 | K22: =E22+G22+I22 -> 0 | L22: =F22+H22+J22 -> 0 | N22: 010206 | P22: 0102 | R22: 3
A23: 010207 유 리 공 사 | D23: 1 | E23: =공종별내역서!F386 -> 0 | F23: =E23*D23 -> 0 | G23: =공종별내역서!H386 -> 0 | H23: =G23*D23 -> 0 | I23: =공종별내역서!J386 -> 0 | J23: =I23*D23 -> 0 | K23: =E23+G23+I23 -> 0 | L23: =F23+H23+J23 -> 0 | N23: 010207 | P23: 0102 | R23: 3
A24: 010208 에어컨 공사 | D24: 1 | E24: =공종별내역서!F410 -> 0 | F24: =E24*D24 -> 0 | G24: =공종별내역서!H410 -> 0 | H24: =G24*D24 -> 0 | I24: =공종별내역서!J410 -> 0 | J24: =I24*D24 -> 0 | K24: =E24+G24+I24 -> 0 | L24: =F24+H24+J24 -> 0 | N24: 010208 | P24: 0102 | R24: 3
A25: 010210 작업부산물(합계미포함) | D25: 1 | E25: =공종별내역서!F434 -> 0 | F25: =E25*D25 -> 0 | G25: =공종별내역서!H434 -> 0 | H25: =G25*D25 -> 0 | I25: =공종별내역서!J434 -> 0 | J25: =I25*D25 -> 0 | K25: =E25+G25+I25 -> 0 | L25: =F25+H25+J25 -> 0 | N25: 010210 | Q25: 1 | R25: 3 | T25: =L25*1 -> 0
A26: 0103 ■ 전 문 점-1 | D26: 1 | E26: =F27+F28+F29+F30+F31+F32+F33 -> 0 | F26: =E26*D26 -> 0 | G26: =H27+H28+H29+H30+H31+H32+H33 -> 0 | H26: =G26*D26 -> 0 | I26: =J27+J28+J29+J30+J31+J32+J33 -> 0 | J26: =I26*D26 -> 0 | K26: =E26+G26+I26 -> 0 | L26: =F26+H26+J26 -> 0 | N26: 0103 | P26: 01 | R26: 2
A27: 010301 가 설 공 사 | D27: 1 | E27: =공종별내역서!F458 -> 0 | F27: =E27*D27 -> 0 | G27: =공종별내역서!H458 -> 0 | H27: =G27*D27 -> 0 | I27: =공종별내역서!J458 -> 0 | J27: =I27*D27 -> 0 | K27: =E27+G27+I27 -> 0 | L27: =F27+H27+J27 -> 0 | N27: 010301 | P27: 0103 | R27: 3
A28: 010302 철 거 공 사 | D28: 1 | E28: =공종별내역서!F482 -> 0 | F28: =E28*D28 -> 0 | G28: =공종별내역서!H482 -> 0 | H28: =G28*D28 -> 0 | I28: =공종별내역서!J482 -> 0 | J28: =I28*D28 -> 0 | K28: =E28+G28+I28 -> 0 | L28: =F28+H28+J28 -> 0 | N28: 010302 | P28: 0103 | R28: 3
A29: 010303 수 장 공 사 | D29: 1 | E29: =공종별내역서!F506 -> 0 | F29: =E29*D29 -> 0 | G29: =공종별내역서!H506 -> 0 | H29: =G29*D29 -> 0 | I29: =공종별내역서!J506 -> 0 | J29: =I29*D29 -> 0 | K29: =E29+G29+I29 -> 0 | L29: =F29+H29+J29 -> 0 | N29: 010303 | P29: 0103 | R29: 3
A30: 010304 금 속 공 사 | D30: 1 | E30: =공종별내역서!F530 -> 0 | F30: =E30*D30 -> 0 | G30: =공종별내역서!H530 -> 0 | H30: =G30*D30 -> 0 | I30: =공종별내역서!J530 -> 0 | J30: =I30*D30 -> 0 | K30: =E30+G30+I30 -> 0 | L30: =F30+H30+J30 -> 0 | N30: 010304 | P30: 0103 | R30: 3
A31: 010305 도 장 공 사 | D31: 1 | E31: =공종별내역서!F554 -> 0 | F31: =E31*D31 -> 0 | G31: =공종별내역서!H554 -> 0 | H31: =G31*D31 -> 0 | I31: =공종별내역서!J554 -> 0 | J31: =I31*D31 -> 0 | K31: =E31+G31+I31 -> 0 | L31: =F31+H31+J31 -> 0 | N31: 010305 | P31: 0103 | R31: 3
A32: 010306 창 호 공 사 | D32: 1 | E32: =공종별내역서!F578 -> 0 | F32: =E32*D32 -> 0 | G32: =공종별내역서!H578 -> 0 | H32: =G32*D32 -> 0 | I32: =공종별내역서!J578 -> 0 | J32: =I32*D32 -> 0 | K32: =E32+G32+I32 -> 0 | L32: =F32+H32+J32 -> 0 | N32: 010306 | P32: 0103 | R32: 3
A33: 010307 유 리 공 사 | D33: 1 | E33: =공종별내역서!F602 -> 0 | F33: =E33*D33 -> 0 | G33: =공종별내역서!H602 -> 0 | H33: =G33*D33 -> 0 | I33: =공종별내역서!J602 -> 0 | J33: =I33*D33 -> 0 | K33: =E33+G33+I33 -> 0 | L33: =F33+H33+J33 -> 0 | N33: 010307 | P33: 0103 | R33: 3
A34: 010308 작업부산물(합계미포함) | D34: 1 | E34: =공종별내역서!F626 -> 0 | F34: =E34*D34 -> 0 | G34: =공종별내역서!H626 -> 0 | H34: =G34*D34 -> 0 | I34: =공종별내역서!J626 -> 0 | J34: =I34*D34 -> 0 | K34: =E34+G34+I34 -> 0 | L34: =F34+H34+J34 -> 0 | N34: 010308 | Q34: 1 | R34: 3 | T34: =L34*1 -> 0
A35: 0104 ■ 전 문 점-2 | D35: 1 | E35: =F36+F37+F38+F39+F40+F41+F42 -> 0 | F35: =E35*D35 -> 0 | G35: =H36+H37+H38+H39+H40+H41+H42 -> 0 | H35: =G35*D35 -> 0 | I35: =J36+J37+J38+J39+J40+J41+J42 -> 0 | J35: =I35*D35 -> 0 | K35: =E35+G35+I35 -> 0 | L35: =F35+H35+J35 -> 0 | N35: 0104 | P35: 01 | R35: 2
A36: 010401 가 설 공 사 | D36: 1 | E36: =공종별내역서!F650 -> 0 | F36: =E36*D36 -> 0 | G36: =공종별내역서!H650 -> 0 | H36: =G36*D36 -> 0 | I36: =공종별내역서!J650 -> 0 | J36: =I36*D36 -> 0 | K36: =E36+G36+I36 -> 0 | L36: =F36+H36+J36 -> 0 | N36: 010401 | P36: 0104 | R36: 3
A37: 010402 철 거 공 사 | D37: 1 | E37: =공종별내역서!F674 -> 0 | F37: =E37*D37 -> 0 | G37: =공종별내역서!H674 -> 0 | H37: =G37*D37 -> 0 | I37: =공종별내역서!J674 -> 0 | J37: =I37*D37 -> 0 | K37: =E37+G37+I37 -> 0 | L37: =F37+H37+J37 -> 0 | N37: 010402 | P37: 0104 | R37: 3
A38: 010403 수 장 공 사 | D38: 1 | E38: =공종별내역서!F698 -> 0 | F38: =E38*D38 -> 0 | G38: =공종별내역서!H698 -> 0 | H38: =G38*D38 -> 0 | I38: =공종별내역서!J698 -> 0 | J38: =I38*D38 -> 0 | K38: =E38+G38+I38 -> 0 | L38: =F38+H38+J38 -> 0 | N38: 010403 | P38: 0104 | R38: 3
A39: 010404 금 속 공 사 | D39: 1 | E39: =공종별내역서!F722 -> 0 | F39: =E39*D39 -> 0 | G39: =공종별내역서!H722 -> 0 | H39: =G39*D39 -> 0 | I39: =공종별내역서!J722 -> 0 | J39: =I39*D39 -> 0 | K39: =E39+G39+I39 -> 0 | L39: =F39+H39+J39 -> 0 | N39: 010404 | P39: 0104 | R39: 3
A40: 010405 도 장 공 사 | D40: 1 | E40: =공종별내역서!F746 -> 0 | F40: =E40*D40 -> 0 | G40: =공종별내역서!H746 -> 0 | H40: =G40*D40 -> 0 | I40: =공종별내역서!J746 -> 0 | J40: =I40*D40 -> 0 | K40: =E40+G40+I40 -> 0 | L40: =F40+H40+J40 -> 0 | N40: 010405 | P40: 0104 | R40: 3
...

Sheet 공종별내역서
A1: [ 부산역 회의실 및 전문점 신축공사 ]
A2: 품 명 | B2: 규 격 | C2: 단위 | D2: 수량 | E2: 재 료 비 | G2: 노 무 비 | I2: 경 비 | K2: 합 계 | M2: 비 고 | N2: 품목코드 | O2: 변수 | P2: 설정 | Q2: 공종코드 | R2: 일위 | S2: 단산 | T2: 자재 | U2: 손료적용 | V2: 손료저장 | W2: 적용율 | X2: JUK1 | Y2: JUK2 | Z2: JUK3 | AA2: JUK4 | AB2: JUK5 | AC2: JUK6 | AD2: JUK7 | AE2: JUK8 | AF2: JUK9 | AG2: JUK10 | AH2: JUK11 | AI2: JUK12 | AJ2: JUK13 | AK2: JUK14 | AL2: JUK15 | AM2: JUK16 | AN2: JUK17 | AO2: JUK18 | AP2: JUK19 | AQ2: JUK20 | AR2: 자재구분 | AS2: 공종구분 | AT2: 공종레벨 | AU2: 공종+자재 | AV2: 고유번호
E3: 단 가 | F3: 금 액 | G3: 단 가 | H3: 금 액 | I3: 단 가 | J3: 금 액 | K3: 단 가 | L3: 금 액
A4: 회의실1
A5: 010101 가 설 공 사 | Q5: 010101
A6: 가설판넬(난연2등급이상) | B6: T:50MM | C6: M2 | D6: 32 | N6: 55BC12188DCF5132A16D0E80C997 | R6: T | S6: F | T6: F | AU6: 01010155BC12188DCF5132A16D0E80C997 | AV6: 4689
A7: 가설판넬설치 | B7: H:5.0 이하 | C7: M2 | D7: 32 | N7: 55BC12188DCF5132A16D0E80C99D | R7: T | S7: F | T7: F | AU7: 01010155BC12188DCF5132A16D0E80C99D | AV7: 4690
A8: 가설판넬해체 | B8: H:5.0 이하 | C8: M2 | D8: 32 | N8: 55BC12188DCF5132A16D0E80C99E | R8: T | S8: F | T8: F | AU8: 01010155BC12188DCF5132A16D0E80C99E | AV8: 4691
A9: 가설출입문 | B9: 1800*2400 | C9: 개소 | D9: 1 | N9: 55BC12188DCF5132A16D0E80C983 | R9: T | S9: F | T9: F | AU9: 01010155BC12188DCF5132A16D0E80C983 | AV9: 5651
A10: 가설현수막 | B10: 안전 문구 | C10: 개소 | D10: 1
A11: 이동식강관말비계 | B11: 1단(2m), 3개월 | C11: 1대 | D11: 2 | N11: 55BC12188DCF40C2B16AAC289295 | R11: T | S11: F | T11: F | AU11: 01010155BC12188DCF40C2B16AAC289295 | AV11: 4693
A12: 건축물현장정리 | B12: 전체 | C12: M2 | D12: 58 | N12: 55BC12188DCF40C2B16C5D58DE35 | R12: T | S12: F | T12: F | AU12: 01010155BC12188DCF40C2B16C5D58DE35 | AV12: 4694
A13: 준공청소 | B13: 전체 | C13: M2 | D13: 58 | N13: 55BC12188DCF40C2B16C5D58DE37 | R13: T | S13: F | T13: F | AU13: 01010155BC12188DCF40C2B16C5D58DE37 | AV13: 4696
A27: [ 합 계 ] | F27: =SUM(F6:F26) -> 0 | H27: =SUM(H6:H26) -> 0 | J27: =SUM(J6:J26) -> 0 | L27: =SUM(L6:L26) -> 0 | N27: TOTAL
A28: 010102 철 거 공 사 | Q28: 010102
A29: 데코타일철거 | B29: 바닥 | C29: M2 | D29: 64 | N29: 55BC12188DCF51D2A16B3928C9C7 | R29: T | S29: F | T29: F | AU29: 01010255BC12188DCF51D2A16B3928C9C7 | AV29: 5652
A30: 텍스철거 | B30: 천정 | C30: M2 | D30: 64 | N30: 55BC12188DCF51D2A16B3BD54397 | R30: T | S30: F | T30: F | AU30: 01010255BC12188DCF51D2A16B3BD54397 | AV30: 5653
A31: 무빙월철거 | C31: M2 | D31: 36 | N31: 55BC12188DCF51D2A16B38012BD4 | R31: T | S31: F | T31: F | AU31: 01010255BC12188DCF51D2A16B38012BD4 | AV31: 5654
A32: 금속판넬철거 | C32: M2 | D32: 63 | N32: 55BC12188DCF51D2A16B38012BD0 | R32: T | S32: F | T32: F | AU32: 01010255BC12188DCF51D2A16B38012BD0 | AV32: 5065
A33: 화이트보드철거 | C33: M2 | D33: 11 | N33: 55BC12188DCF51D2A16B38012BD5 | R33: T | S33: F | T33: F | AU33: 01010255BC12188DCF51D2A16B38012BD5 | AV33: 5655
A34: 도어철거 | B34: 900*3000 | C34: 개소 | D34: 1 | N34: 55BC12188DCF51D2A16B3D833C3A | R34: T | S34: F | T34: F | AU34: 01010255BC12188DCF51D2A16B3D833C3A | AV34: 5068
A35: 집기이설 | C35: SET | D35: 1 | N35: 55BC12188DCF51D2A16B3BD54660 | R35: T | S35: F | T35: F | AU35: 01010255BC12188DCF51D2A16B3BD54660 | AV35: 5656
A36: 폐자재처리수수료 | B36: 건축폐재류 | C36: TON | D36: 9.8 | N36: 55BC12188DCF51D2A1690B2CAF0F | R36: T | S36: F | T36: F | AU36: 01010255BC12188DCF51D2A1690B2CAF0F | AV36: 4884
A37: 건설폐기물상차·운반비-중간처리 | B37: 16톤압롤트럭, 30km | C37: TON | D37: 9.8 | N37: 55BC12188DCF51D2A1690A03D712 | R37: T | S37: F | T37: F | AU37: 01010255BC12188DCF51D2A1690A03D712 | AV37: 4885
A51: [ 합 계 ] | F51: =SUM(F29:F50) -> 0 | H51: =SUM(H29:H50) -> 0 | J51: =SUM(J29:J50) -> 0 | L51: =SUM(L29:L50) -> 0 | N51: TOTAL
A52: 010103 수 장 공 사 | Q52: 010103
A53: 데코타일 깔기 | B53: 비닐타일, 3*450*450mm | C53: M2 | D53: 58 | N53: 55BC12188DCF5132A16ABFC0273C | R53: T | S53: F | T53: F | AU53: 01010355BC12188DCF5132A16ABFC0273C | AV53: 5666
A54: 불연천정판 | B54: M-Bar용,12*300*600 | C54: M2 | D54: 58 | N54: 55BC12188DCF404261605C49C623 | R54: T | S54: F | T54: F | AU54: 01010355BC12188DCF404261605C49C623 | AV54: 4711
A55: DRY WALL(C-50*40*0.8T) | B55: 차음GS12.5t*2겹*양면 | C55: M2 | D55: 102 | N55: 55BC12188DCF5132A163089F0175 | R55: T | S55: F | T55: F | AU55: 01010355BC12188DCF5132A163089F0175 | AV55: 5667
A56: 미네랄울설치(벽) | B56: 펠트, 밀도60kg/㎥, 50mm | C56: M2 | D56: 102 | N56: 55BC12188DCF7C42916D670AC06C | R56: T | S56: F | T56: F | AU56: 01010355BC12188DCF7C42916D670AC06C | AV56: 5668
A57: 차음패널(목모보드) | B57: 15T*1220*2440mm(㎡) | C57: M2 | D57: 62 | M57: 시공도 | N57: 55BC121850A047F2316C05FDD4FC | R57: F | S57: F | T57: T | AU57: 01010355BC121850A047F2316C05FDD4FC | AV57: 5669
A58: 합판 벽붙이기 | B58: 9.0*1겹 | C58: M2 | D58: 12 | N58: 55BC12188DCF404261605D503903 | R58: T | S58: F | T58: F | AU58: 01010355BC12188DCF404261605D503903 | AV58: 5665
A59: MDF걸레받이 | B59: T=9, H=100 | C59: M | D59: 29 | N59: 55BC12188DCF5132A1699712EB23 | R59: T | S59: F | T59: F | AU59: 01010355BC12188DCF5132A1699712EB23 | AV59: 5297
A60: 빌트인가구 | B60: 1580*510*3000 | C60: EA | D60: 1 | N60: 53491208C30FFC12416BBAC1EC | R60: F | S60: F | T60: T | AU60: 01010353491208C30FFC12416BBAC1EC | AV60: 5664
A61: 석고판못붙임(천정) | B61: T=9.5*1겹 | C61: M2 | D61: 58
A62: 천정타공 | C62: M | D62: 21
A74: [ 합 계 ] | F74: =SUM(F53:F73) -> 0 | H74: =SUM(H53:H73) -> 0 | J74: =SUM(J53:J73) -> 0 | L74: =SUM(L53:L73) -> 0 | N74: TOTAL
A75: 010104 금 속 공 사 | Q75: 010104
A76: 경량철골천정틀 | B76: M-BAR H:1m 이상. 인써트 유 | C76: M2 | D76: 29 | N76: 55BC12188DCF5162716D71B0CB5F | R76: T | S76: F | T76: F | AU76: 01010455BC12188DCF5162716D71B0CB5F | AV76: 4718
A77: 일반구조용각형강관 | B77: 20*20*1.4mm | C77: M | D77: 10
...
