Workbook
Name _: #REF!
Name _?: #REF!
Name _?: #REF!
Name __: #REF!
Name __: #REF!
Name ___: #REF!
Name ___: #REF!
Name ____: #REF!
Name ____: #REF!
Name _____: #REF!
Name _____: #REF!
Name ______: #REF!
Name ______: #REF!
Name _______: #REF!
Name _______: #REF!
Name __________: #REF!
Name __________: #REF!
Name _____________0: #REF!
Name _____________0: #REF!
Name _____________11: #REF!
Name _____________11: #REF!
Name _____________12: #REF!
Name _____________12: #REF!
Name __________0: #REF!
Name __________0: #REF!
Name __________11: #REF!
Name __________11: #REF!
Name __________12: #REF!
Name __________12: #REF!
Name _________0: #REF!
Name _________0: #REF!
Name _________10: #REF!
Name _________10: #REF!
Name _________11: #REF!
Name _________11: #REF!
Name _________12: #REF!
Name _________12: #REF!
Name ________0: #REF!
Name ________0: #REF!
Name ________10: #REF!
Name ________10: #REF!
Name ________11: #REF!
Name ________11: #REF!
Name ________12: #REF!
Name ________12: #REF!
Name _______0: #REF!
Name _______0: #REF!
Name ______0: #REF!
Name ______0: #REF!
Name ______11: #REF!
Name ______11: #REF!
Name ______12: #REF!
Name ______12: #REF!
Name _____0: #REF!
Name _____0: #REF!
Name _____10: #REF!
Name _____10: #REF!
Name _____11: #REF!
Name _____11: #REF!
Name _____12: #REF!

Sheet 01-원가계산서- x
A1: * 공사 원가 계산서 *
A2: 공사명 : ㈜CJ제일제당 제주물류통합창고 신축 소방공사 | F2: ="일금 "&NUMBERSTRING(G2,1)&" 원정" -> 일금 일십오억일천이백사십이만육천육십일 원정 | G2: =D33 -> 1512426061
A3: 비 목 | D3: 금 액 | E3: 구 성 비 | G3: 비 고
A4: 순 공 사 원 가 | B4: 재 료 비 | C4: 직 접 재 료 비 | D4: =[14]내역서집계!F16 -> 535171121
C5: 간 접 재 료 비
C6: 작업설, 부산물 (△)
C7: [ 소 계 ] | D7: =SUM(D4:D6) -> 535171121
B8: 노무비 | C8: 직 접 노 무 비 | D8: =[14]내역서집계!G16 -> 453059122
C9: 간 접 노 무 비 | D9: =ROUNDDOWN(D8*F9,0) -> 35791670 | E9: 직접노무비 * | F9: 0.079
C10: [ 소 계 ] | D10: =SUM(D8:D9) -> 488850792
B11: 경 비 | C11: 운 반 비 | D11: 0
C12: 기 계 경 비 | D12: =[14]내역서집계!H16 -> 176854
C13: 가 설 비 | D13: 0
C14: 산 재 보 험 료 | D14: =ROUNDDOWN(D10*F14,0) -> 19798457 | E14: 노무비 * | F14: 0.0405
C15: 고 용 보 험 료 | D15: =ROUNDDOWN(D10*F15,0) -> 4253001 | E15: 노무비 * | F15: 0.0087
C16: 건 강 보 험 료 | D16: =ROUNDDOWN(D8*F16,0) -> 14135444 | E16: 직접노무비 * | F16: 0.0312
C17: 연 금 보 험 료 | D17: =ROUNDDOWN(D8*F17,0) -> 20387660 | E17: 직접노무비 * | F17: 0.045
C18: 노인장기요양보험료 | D18: =ROUNDDOWN(D16*F18,0) -> 1043195 | E18: 건강보험료 * | F18: 0.0738
C19: 퇴 직 공 제 부 금 비 | D19: =ROUNDDOWN(D8*F19,0) -> 10420359 | E19: 직접노무비 * | F19: 0.023
C20: 산업안전보건관리비 | D20: =TRUNC((D7+D8)*F20, 0) -> 28955146 | E20: (재료비+직노)* | F20: 0.0293
C21: 기 타 경 비 | D21: =ROUNDDOWN((D7+D10)*F21,0) -> 56321205 | E21: (재료비+노무비) * | F21: 0.055
C25: [ 소 계 ] | D25: =SUM(D11:D24) -> 155491321
A26: 계 | D26: =ROUNDDOWN((D7+D10+D25),0)+1 -> 1179513235
A27: 일 반 관 리 비 | D27: =ROUNDDOWN(D26*F27,0) -> 70770794 | E27: 계 * | F27: 0.06
A28: 이 윤 | D28: =ROUNDDOWN((D10+D25+D27)*F28,0) -> 107266936 | E28: (노무비+경비+일반관리비) * | F28: 0.15
A29: 공 급 가 액 | D29: =SUM(D26:D28)+F29 -> 1357550965 | E29: 만단위 절삭
A30: 부 가 가 치 세 | D30: =ROUNDDOWN(D29*F30,0) -> 135755096 | E30: 공급가액 * | F30: 0.1
A31: 도 급 액 | D31: =ROUNDDOWN((D29+D30),0) -> 1493306061
A32: 대 관 수 수 료 | D32: =[14]대관수수료!G62 -> 19120000 | E32: (한전불입금 및 사용전검사)
A33: 총 공 사 비 | D33: =SUM(D31:D32) -> 1512426061

Sheet 설계예산서
A1: 설 계 년월일 | C1: 2018년 | E1: 설계자 | I1: 담당 | L1: 상무 | O1: 상임이사 | S1: 조합장
A5: 2018년도
A6: 부산역 3층 전문식당가 소방 설비공사
A7: 설 계 예 산 서
H9: ◎ 공 사 개 요
I10: ='내역 집계(전기)'!B3 -> #REF! | M10: 1식
I11: ='내역 집계(전기)'!B4 -> 2. 자동화재탐지 설비공사 | M11: 1식
I12: ='내역 집계(전기)'!B5 -> 3. 유도등 설비공사 | M12: 1식
I13: ='내역 집계(전기)'!B6 -> 4. 비상방송 설비공사 | M13: 1식
I14: ='내역 집계(전기)'!B7 -> 5. 비상조명 설비공사 | M14: 1식
S15: =공사원가계산서!H24 -> 0
G17: 총 공사비 : | I17: =P17 -> 0 | O17: [￦ | P17: =공사원가계산서!D23 -> 0 | S17: ]
G18: 부가가치세 : | I18: =P18 -> 0 | O18: [￦ | P18: =공사원가계산서!D24 -> 0 | S18: ]
G19: 도급공사비 : | I19: =P19 -> 0 | O19: [￦ | P19: =공사원가계산서!D25 -> 0 | S19: ]

Sheet 공사원가계산서
A1: 공 사 명 : | C1: =설계예산서!A6 -> 부산역 3층 전문식당가 소방 설비공사
A2: 구 분 | D2: 금 액 | E2: 구 성 비 | H2: 비 고
A3: 순 공 사 비 | B3: 재료비 | C3: 직 접 재 료 비 | D3: ='내역 집계(전기)'!F16 -> 0
C4: 간 접 재 료 비
C5: 작업실 부산물
C6: 소 계 | D6: =SUM(D3:D5) -> 0
B7: 노무비 | C7: 직 접 노 무 비 | D7: ='내역 집계(전기)'!G16 -> 0
C8: 간 접 노 무 비 | D8: =TRUNC(+E8*G8) -> 0 | E8: =D7 -> 0 | F8: * | G8: 0.079 | H8: 직접노무비
C9: 소 계 | D9: =SUM(D7:D8) -> 0
B10: 경 비 | C10: 기 계 경 비 | D10: ='내역 집계(전기)'!H16 -> 0
C11: 산 재 보 험 료 | D11: =TRUNC(+E11*G11) -> 0 | E11: =D9 -> 0 | F11: * | G11: 0.0405 | H11: 노무비
C12: 고 용 보 험 | D12: =TRUNC(+E12*G12) -> 0 | E12: =D9 -> 0 | F12: * | G12: 0.0087 | H12: 노무비
C13: 건 강 보 험 료 | D13: =TRUNC(+E13*G13) -> 0 | E13: =D7 -> 0 | F13: * | G13: 0.0312 | H13: 직접노무비
C14: 연 금 보 험 료 | D14: =TRUNC(+E14*G14) -> 0 | E14: =D7 -> 0 | F14: * | G14: 0.045 | H14: 직접노무비
C15: 노인장기요양보험료 | E15: =D13 -> 0 | F15: * | G15: 0.0738 | H15: 건강보험료
C16: 산업안전보건관리비 | D16: =TRUNC(+E16*G16) -> 0 | E16: =D6+D7 -> 0 | F16: * | G16: 0.0293 | H16: (재료비+직접노무비)*율
C17: 기 타 경 비 | D17: =TRUNC(+E17*G17) -> 0 | E17: =D6+D9 -> 0 | F17: * | G17: 0.055 | H17: 재료비+노무비
C18: 퇴직공제부금비 | E18: =D7 -> 0 | F18: * | G18: 0.023 | H18: 직접노무비
C19: 소 계 | D19: =SUM(D10:D18) -> 0
A20: 일 반 관 리 비 | D20: =TRUNC(+E20*G20) -> 0 | E20: =D6+D9+D19 -> 0 | F20: * | G20: 0.06 | H20: 재료비+노무비+경비
A21: 누 계 | D21: =SUM(D6,D9,D19,D20) -> 0
A22: 이 윤 (%) | D22: =TRUNC(+E22*G22) -> 0 | E22: =SUM(D9,D19,D20) -> 0 | F22: * | G22: 0.15 | H22: 노무비+경비+일반관리비
A23: 총 원 가 | D23: =ROUNDDOWN(SUM(D21:D22),-4) -> 0 | H23: 천단위 이하 절사
A24: 부 가 가 치 세 | D24: =TRUNC(+E24*G24) -> 0 | E24: =D23 -> 0 | F24: * | G24: 0.1
A25: 도 급 공 사 비 | D25: =SUM(D23:D24) -> 0
A28: 총 합 계 | D28: =SUM(D25:D27) -> 0

Sheet 집계표-x
A1: 공종 집계표
A2: 공 사 명 | B2: 에이스침대 구미점 신축 소방공사
A3: 공 사 비 | B3: =TEXT(H21,"[DBNUM4]")&"원정" -> 영원정 | E3: =H21 -> 0
A4: 공 종 명 | C4: 단 위 | D4: 수 량 | E4: 재 료 비 | F4: 노 무 비 | G4: 경 비 | H4: 합 계 | I4: 비 고
A5: =내역서!B3 -> #REF! | B5: 식 | C5: 1 | D5: 1 | E5: =내역서!G3 -> 0 | F5: =내역서!I3 -> 0 | G5: =내역서!K3 -> 0 | H5: =SUM(E5:G5) -> 0
A6: =내역서!B59 -> 2. 자동화재탐지 설비공사 | B6: 식 | C6: 1 | D6: 1 | E6: =내역서!G59 -> 0 | F6: =내역서!I59 -> 0 | G6: =내역서!K59 -> 0 | H6: =SUM(E6:G6) -> 0
A7: =내역서!B87 -> 3. 유도등 설비공사 | B7: 식 | C7: 1 | D7: 1 | E7: =내역서!G87 -> 0 | F7: =내역서!I87 -> 0 | G7: =내역서!K87 -> 0 | H7: =SUM(E7:G7) -> 0
A21: 합 계 | E21: =SUM(E5:E20) -> 0 | F21: =SUM(F5:F20) -> 0 | G21: =SUM(G5:G20) -> 0 | H21: =SUM(E21:G21) -> 0

Sheet 설계예산서 
A1: 설 계 년월일 | C1: 2018년 | E1: 설계자 | I1: 담당 | L1: 상무 | O1: 상임이사 | S1: 조합장
A5: 2018년도
A6: 부산역 3층 전문점 소방설비공사
A7: 설 계 예 산 서
H9: ◎ 공 사 개 요
I10: ='내역서집계(전기+기계)'!B3 -> 1. 전기소방 공사 | M10: 1식
I11: ='내역서집계(전기+기계)'!B4 -> 2. 기계소방 공사 | M11: 1식
S15: ='공사 원가계산서'!H24 -> 0
G17: 총 공사비 : | I17: =P17 -> 0 | O17: [￦ | P17: ='공사 원가계산서'!D23 -> 0 | S17: ]
G18: 부가가치세 : | I18: =P18 -> 0 | O18: [￦ | P18: ='공사 원가계산서'!D24 -> 0 | S18: ]
G19: 도급공사비 : | I19: =P19 -> 0 | O19: [￦ | P19: ='공사 원가계산서'!D25 -> 0 | S19: ]

Sheet 공사 원가계산서
A1: 공 사 명 : | C1: ='설계예산서 '!A6 -> 부산역 3층 전문점 소방설비공사
A2: 구 분 | D2: 금 액 | E2: 구 성 비 | H2: 비 고
A3: 순 공 사 비 | B3: 재료비 | C3: 직 접 재 료 비 | D3: ='내역서집계(전기+기계)'!F16 -> 0
C4: 간 접 재 료 비 | H4: 해당없음
C5: 작업실 부산물
C6: 소 계 | D6: =SUM(D3:D5) -> 0
B7: 노무비 | C7: 직 접 노 무 비 | D7: ='내역서집계(전기+기계)'!G16 -> 0
C8: 간 접 노 무 비 | D8: =TRUNC(+E8*G8) -> 0 | E8: =D7 -> 0 | F8: * | G8: 0.079 | H8: 직접노무비
C9: 소 계 | D9: =SUM(D7:D8) -> 0
B10: 경 비 | C10: 기 계 경 비 | D10: ='내역서집계(전기+기계)'!H16 -> 0
C11: 산 재 보 험 료 | D11: =TRUNC(+E11*G11) -> 0 | E11: =D9 -> 0 | F11: * | G11: 0.0405 | H11: 노무비
C12: 고 용 보 험 | D12: =TRUNC(+E12*G12) -> 0 | E12: =D9 -> 0 | F12: * | G12: 0.0087 | H12: 노무비
C13: 건 강 보 험 료 | D13: =TRUNC(+E13*G13) -> 0 | F13: * | H13: 해당없음
C14: 연 금 보 험 료 | D14: =TRUNC(+E14*G14) -> 0 | F14: * | H14: 해당없음
C15: 노인장기요양보험료 | D15: =TRUNC(+E15*G15) -> 0 | E15: =D13 -> 0 | F15: * | H15: 해당없음
C16: 산업안전보건관리비 | D16: =TRUNC(+E16*G16) -> 0 | E16: =D6+D7 -> 0 | F16: * | G16: 0.0293 | H16: (재료비+직접노무비)*율
C17: 기 타 경 비 | D17: =TRUNC(+E17*G17) -> 0 | E17: =D6+D9 -> 0 | F17: * | G17: 0.055 | H17: 재료비+노무비
C18: 퇴직공제부금비 | F18: * | H18: 해당없음
C19: 소 계 | D19: =SUM(D10:D18) -> 0
A20: 일 반 관 리 비 | D20: =TRUNC(+E20*G20) -> 0 | E20: =D6+D9+D19 -> 0 | F20: * | G20: 0.06 | H20: 재료비+노무비+경비
A21: 누 계 | D21: =SUM(D6,D9,D19,D20) -> 0
A22: 이 윤 (%) | E22: =SUM(D9,D19,D20) -> 0 | F22: * | G22: 0.15 | H22: 노무비+경비+일반관리비
A23: 총 원 가 | D23: =ROUNDDOWN(SUM(D21:D22),0) -> 0 | H23: 천단위 이하 절사
A24: 부 가 가 치 세 | D24: =TRUNC(+E24*G24) -> 0 | E24: =D23 -> 0 | F24: * | G24: 0.1
A25: 도 급 공 사 비 | D25: =SUM(D23:D24) -> 0
A28: 총 합 계 | D28: =SUM(D25:D27) -> 0

Sheet 내역서집계(전기+기계)
B1: 공 종 | D1: 수 량 | E1: 단 위 | F1: 재 료 비 | G1: 노 무 비 | H1: 경 비 | I1: 합 계 | J1: 비 고
A2: 제목 | B2: ='공사 원가계산서'!A1 -> 공 사 명 : | C2: ='설계예산서 '!A6 -> 부산역 3층 전문점 소방설비공사
B3: 1. 전기소방 공사 | D3: 1 | E3: 식 | F3: ='내역 집계(전기)'!F16 -> 0 | G3: ='내역 집계(전기)'!G16 -> 0 | H3: =[15]내역서집계!H16 -> 0 | I3: =F3+G3+H3 -> 0
B4: 2. 기계소방 공사 | D4: 1 | E4: 식 | F4: ='내역 집계(기계)'!E20 -> 0 | G4: ='내역 집계(기계)'!F20 -> 0 | H4: ='내역 집계(기계)'!G20 -> 0 | I4: =F4+G4+H4 -> 0
B16: 합 계 | F16: =SUM(F3:F15) -> 0 | G16: =SUM(G3:G15) -> 0 | H16: =SUM(H3:H15) -> 0 | I16: =F16+G16+H16 -> 0
G18: 0

Sheet 내역 집계(전기)
B1: 공 종 | D1: 수 량 | E1: 단 위 | F1: 재 료 비 | G1: 노 무 비 | H1: 경 비 | I1: 합 계 | J1: 비 고
A2: 제목 | B2: =공사원가계산서!A1 -> 공 사 명 : | C2: 부산역 3층 전문점 소방설비공사 <전기분야>
B3: =내역서!B3 -> #REF! | D3: 1 | E3: 식 | F3: =내역서!G3 -> 0 | G3: =내역서!I3 -> 0 | H3: =내역서!K3 -> 0 | I3: =F3+G3+H3 -> 0
B4: =내역서!B59 -> 2. 자동화재탐지 설비공사 | D4: 1 | E4: 식 | F4: =내역서!G59 -> 0 | G4: =내역서!I59 -> 0 | I4: =F4+G4+H4 -> 0
B5: =내역서!B87 -> 3. 유도등 설비공사 | D5: 1 | E5: 식 | F5: =내역서!G87 -> 0 | G5: =내역서!I87 -> 0 | I5: =F5+G5+H5 -> 0
B6: =내역서!B115 -> 4. 비상방송 설비공사 | D6: 1 | E6: 식 | F6: =내역서!G115 -> 0 | G6: =내역서!I115 -> 0 | I6: =F6+G6+H6 -> 0
B7: =내역서!B143 -> 5. 비상조명 설비공사 | D7: 1 | E7: 식 | F7: =내역서!G143 -> 0 | G7: =내역서!I143 -> 0 | H7: =내역서!K143 -> 0 | I7: =F7+G7+H7 -> 0
B16: 합 계 | F16: =SUM(F3:F15) -> 0 | G16: =SUM(G3:G15) -> 0 | H16: =SUM(H3:H15) -> 0 | I16: =F16+G16+H16 -> 0
G18: 0

Sheet 내역 집계(기계)
A1: 공종 집계표
A2: 공 사 명 | B2: 부산역 3층 전문점 소방설비공사(기계분야)
A3: 공 사 비 | B3: =TEXT(H20,"[DBNUM4]")&"원정" -> 영원정 | H3: =H20 -> 0
A4: 공 종 명 | C4: 단 위 | D4: 수 량 | E4: 재 료 비 | F4: 노 무 비 | G4: 경 비 | H4: 합 계 | I4: 비 고
A5: ='01-기계소방내역'!A5 -> #REF! | C5: 식 | D5: 1 | E5: ='01-기계소방내역'!F185 -> 0 | F5: ='01-기계소방내역'!H185 -> 0 | G5: ='01-기계소방내역'!J185 -> 0 | H5: =SUM(E5:G5) -> 0
A20: 합 계 | E20: =SUM(E5:E6) -> 0 | F20: =SUM(F5:F6) -> 0 | G20: =SUM(G5:G6) -> 0 | H20: =SUM(E20:G20) -> 0

Sheet 내역서
A1: CODE | B1: 품 명 | C1: 규 격 | D1: 단위 | E1: 수량 | F1: 재 료 비 | H1: 노 무 비 | J1: 경 비 | L1: 합 계 | M1: 비 고
F2: 단 가 | G2: 금 액 | H2: 단 가 | I2: 금 액 | J2: 단 가 | K2: 금 액 | L2: 금 액
A3: 제목 | B3: =#REF! -> #REF! | G3: =G58 -> 0 | I3: =I58 -> 0 | K3: =K58 -> 0 | L3: =L58 -> 0
A4: =#REF! -> #REF! | B4: 강제전선관 | C4: ST 16C | D4: M | E4: 57
A5: =#REF! -> #REF! | B5: 강제전선관 | C5: ST 22C | D5: M | E5: 71
A6: =#REF! -> #REF! | B6: 강제전선관 | C6: ST 36C | D6: M | E6: 11
A7: =#REF! -> #REF! | B7: 플렉시블 전선관 | C7: GW 16C 방수 | D7: M | E7: 115
A8: =#REF! -> #REF! | B8: 플렉시블 전선관 | C8: GW 22C 방수 | D8: M | E8: 84
A9: =#REF! -> #REF! | B9: 플렉시블 전선관 | C9: GW 36C 방수 | D9: M | E9: 18
A10: =#REF! -> #REF! | B10: 450/750V 저독성 가교 폴리올레핀 | C10: HFIX 2.5㎟ | D10: M | E10: 1373
A11: =#REF! -> #REF! | B11: 제어용 차폐 케이블 | C11: H-CVV-SB 2.5㎟/2C | D11: M | E11: 28
A12: =#REF! -> #REF! | B12: 노말밴드 | C12: ST36 | D12: EA | E12: 2
A13: =#REF! -> #REF! | B13: 파이프크램프 | C13: 16C | D13: EA | E13: 3
A14: =#REF! -> #REF! | B14: 파이프크램프 | C14: 22C | D14: EA | E14: 21
A15: =#REF! -> #REF! | B15: 파이프크램프 | C15: 36C | D15: EA | E15: 18
... A24: =#REF! -> #REF! | B24: 화재수신반 | C24: P형 1급 5회로용 | D24: 면 | E24: 1
A25: =#REF! -> #REF! | B25: 기존 R형 수신반 프로그램 및 CRT 변경비 | C25: 0 | D25: 식 | E25: 1
A26: =#REF! -> #REF! | B26: 시각경보기 | C26: 0 | D26: EA | E26: 9
A27: =#REF! -> #REF! | B27: 휴대용비상조명등 | C27: FI인증, 건전지형 | D27: EA | E27: 10
A28: =#REF! -> #REF! | B28: 유니스트러트판넬 | C28: 42x42x2.6t | D28: EA | E28: 4
A29: =#REF! -> #REF! | B29: 너트 | C29: 3/8" | D29: EA | E29: 44
A30: =#REF! -> #REF! | B30: 스트롱앙카 | C30: 3/8" | D30: EA | E30: 42
A31: =#REF! -> #REF! | B31: 행거볼트 | C31: M10 | D31: EA | E31: 22
B33: 전선관부속품비 | C33: 전선관의 15% | D33: 식 | E33: 1
B34: 잡자재비 | C34: 배관배선의 2% | D34: 식 | E34: 1
B35: 노무비 | C35: 내선전공 | D35: 인 | E35: 69.62
B36: 노무비 | C36: 저압케이블전공 | D36: 인 | E36: 0.432
B37: 공구손료 | C37: 노무비의 3% | D37: 식 | E37: 1
A58: 계 | B58: 합 계
A59: 제목 | B59: 2. 자동화재탐지 설비공사
A60: =#REF! -> #REF! | B60: 플렉시블 전선관 | C60: GW 16C 방수 | D60: M | E60: 177
A61: =#REF! -> #REF! | B61: 1종 금속제 가요전선관 | C61: 고장력 16C 방수 | D61: M | E61: 24
A62: =#REF! -> #REF! | B62: 1종 가요관 콘넥타 | C62: GW 16C 방수 | D62: EA | E62: 66
A63: =#REF! -> #REF! | B63: 1종 가요관 콘넥타 | C63: 16C 방수 | D63: EA | E63: 22
A64: =#REF! -> #REF! | B64: 강제전선관 | C64: ST 16C | D64: M | E64: 3
A65: =#REF! -> #REF! | B65: 450/750V 저독성 가교 폴리올레핀 | C65: HFIX 1.5㎟ | D65: M | E65: 550
A66: =#REF! -> #REF! | B66: 아우트레트 박스 | C66: 8각 54mm | D66: EA | E66: 32
A67: =#REF! -> #REF! | B67: 박스 카바 | C67: 8각 평형 | D67: EA | E67: 32
A68: =#REF! -> #REF! | B68: 화재감지기 | C68: 차동식 스포트형 | D68: EA | E68: 24
A69: =#REF! -> #REF! | B69: 화재감지기 | C69: 정온식 스포트형 | D69: EA | E69: 7
...

Sheet 01-기계소방내역
A1: - 내 역 서 -
A2: 공사명 : 부산역 3층 전문식당가 소방설비공사(기계)
A3: 품 명 | B3: 규 격 | C3: 단위 | D3: 수량 | E3: 재 료 비 | G3: 노 무 비 | I3: 경 비 | K3: 합 계 | M3: 비 고
E4: 단 가 | F4: 금 액 | G4: 단 가 | H4: 금 액 | I4: 단 가 | J4: 금 액 | K4: 단 가 | L4: 금 액
A5: =#REF! -> #REF!
A6: =#REF! -> #REF! | B6: =#REF! -> #REF! | C6: =#REF! -> #REF! | D6: =#REF! -> #REF! | E6: =#REF! -> #REF! | F6: =TRUNC(D6*E6) -> #REF! | K6: =E6+G6+I6 -> #REF! | L6: =F6+H6+J6 -> #REF!
A7: =#REF! -> #REF! | B7: =#REF! -> #REF! | C7: =#REF! -> #REF! | D7: =#REF! -> #REF! | E7: =#REF! -> #REF! | F7: =TRUNC(D7*E7) -> #REF! | K7: =E7+G7+I7 -> #REF! | L7: =F7+H7+J7 -> #REF!
A8: =#REF! -> #REF! | B8: =#REF! -> #REF! | C8: =#REF! -> #REF! | D8: =#REF! -> #REF! | E8: =#REF! -> #REF! | F8: =TRUNC(D8*E8) -> #REF! | K8: =E8+G8+I8 -> #REF! | L8: =F8+H8+J8 -> #REF!
A9: =#REF! -> #REF! | B9: =#REF! -> #REF! | C9: =#REF! -> #REF! | D9: =#REF! -> #REF! | E9: =#REF! -> #REF! | F9: =TRUNC(D9*E9) -> #REF! | K9: =E9+G9+I9 -> #REF! | L9: =F9+H9+J9 -> #REF!
A10: =#REF! -> #REF! | B10: =#REF! -> #REF! | C10: =#REF! -> #REF! | D10: =#REF! -> #REF! | E10: =#REF! -> #REF! | F10: =TRUNC(D10*E10) -> #REF! | K10: =E10+G10+I10 -> #REF! | L10: =F10+H10+J10 -> #REF!
A11: =#REF! -> #REF! | B11: =#REF! -> #REF! | C11: =#REF! -> #REF! | D11: =#REF! -> #REF! | E11: =#REF! -> #REF! | F11: =TRUNC(D11*E11) -> #REF! | K11: =E11+G11+I11 -> #REF! | L11: =F11+H11+J11 -> #REF!
A12: 배관용 탄소강관 | B12: 백관 (SPP), D40, 반제품 | C12: M | D12: 24
A13: 배관용 탄소강관 | B13: 백관 (SPP), D32, 반제품 | C13: M | D13: 10
A14: 배관용 탄소강관 | B14: 백관 (SPP), D25, 반제품 | C14: M | D14: 287
A15: 용접식 관이음쇠 | B15: 백엘보 (용접) D150 | C15: EA | D15: 0
A16: 용접식 관이음쇠 | B16: 백엘보 (용접) D100 | C16: EA | D16: 0
A17: 용접식 관이음쇠 | B17: 백엘보 (용접) D80 | C17: EA | D17: 0
A18: 용접식 관이음쇠 | B18: 백엘보 (용접) D65 | C18: EA | D18: 0
A19: 용접식 관이음쇠 | B19: 백엘보 (용접) D50 | C19: EA | D19: 0
A20: 용접식 관이음쇠 | B20: 백엘보 (용접) D40 | C20: EA | D20: 0
A21: 나사식 강관제 관이음쇠 | B21: 백엘보 (나사) D50 | C21: EA | D21: 0
A22: 나사식 강관제 관이음쇠 | B22: 백엘보 (나사) D40 | C22: EA | D22: 3
A23: 나사식 강관제 관이음쇠 | B23: 백엘보 (나사) D32 | C23: EA | D23: 0
... A81: 알람밸브 | B81: D65 10kg | C81: EA | D81: 0
A82: 압력계설치(백관) | C82: EA | D82: 0
A83: 옥내소화전 이설 | C83: 개소 | D83: 1
A84: 옥내소화전카바(전면) | B84: 스텐1.6T | C84: 개소 | D84: 0
A85: 템퍼스위치 | C85: EA | D85: 0
A86: 스프링클러헤드 | B86: 폐쇄상향식, D15*72°C | C86: EA | D86: 64
A87: 스프링클러헤드 | B87: 폐쇄하향식, D15*72°C | C87: EA | D87: 84
A88: 스프링클러헤드 | B88: 폐쇄하향식, D15*103°C | C88: EA | D88: 16
A89: 스프링클러헤드 철거 | B89: 폐쇄하향식, D15*72°C | C89: EA | D89: 164
A90: 자동배수밸브 | B90: D20 | C90: EA | D90: 0
A91: 용접 합후렌지 | B91: D150 10kg | C91: 개소 | D91: 0 | M91: 대가 5-1
A92: 간이스프링클러펙케이지 | B92: 수도직결형/1,000lit | C92: SET | D92: 0
A93: 용접 합후렌지 | B93: D100 | C93: 개소 | D93: 0 | M93: 대가 5-3
A94: 용접 합후렌지 | B94: D80 | C94: 개소 | D94: 0 | M94: 대가 5-4
A95: 용접 합후렌지 | B95: D65 | C95: 개소 | D95: 0 | M95: 대가 5-5
A96: 용접 합후렌지 | B96: D50 | C96: 개소 | D96: 0 | M96: 대가 5-6
A97: 용접 합후렌지 | B97: D40 | C97: 개소 | D97: 0 | M97: 대가 5-7
...

Sheet 노임단가
A1: 식별 | B1: 직 종 | C1: 단위 | D1: 2018년 하반기노임 | E1: 2018년 상반기노임 | F1: 2017년 하반기노임 | G1: 2017년 상반기노임 | H1: 2016년 하반기노임 | I1: 2016년 상반기노임
A2: code | D2: 2018.9.1 | E2: 2018.1.1 | F2: 2017.9.1 | G2: 2017.1.1 | H2: 2016.9.1 | I2: 2016.1.1
A3: 1001 | B3: 작업반장 | C3: 인 | D3: 145013 | E3: 137535 | F3: 132631 | G3: 128126 | H3: 124304 | I3: 117612
A4: 1002 | B4: 보통인부 | C4: 인 | D4: 118130 | E4: 109819 | F4: 106846 | G4: 102628 | H4: 99882 | I4: 94338
A5: 1003 | B5: 특별인부 | C5: 인 | D5: 141507 | E5: 133417 | F5: 127391 | G5: 123074 | H5: 120716 | I5: 115272
A6: 1004 | B6: 조력공 | C6: 인 | D6: 127124 | E6: 120416 | F6: 116344 | G6: 112847 | H6: 110194 | I6: 105790
A7: 1005 | B7: 제도사 | C7: 인 | D7: 153608 | E7: 144980 | F7: 138832 | G7: 132819 | H7: 128795 | I7: 122341
A8: 1006 | B8: 비계공 | C8: 인 | D8: 208195 | E8: 196261 | F8: 187771 | G8: 180153 | H8: 175367 | I8: 167860
A9: 1007 | B9: 형틀목공 | C9: 인 | D9: 197929 | E9: 189303 | F9: 179290 | G9: 174036 | H9: 168448 | I9: 160431
A10: 1008 | B10: 철근공 | C10: 인 | D10: 199266 | E10: 189585 | F10: 179665 | G10: 170033 | H10: 164864 | I10: 154424
A11: 1009 | B11: 철공 | C11: 인 | D11: 177994 | E11: 170500 | F11: 162422 | G11: 156492 | H11: 151564 | I11: 146509
A12: 1010 | B12: 철판공 | C12: 인 | D12: 160892 | E12: 153766 | F12: 148955 | G12: 143643 | H12: 140589 | I12: 131821
A13: 1011 | B13: 철골공 | C13: 인 | D13: 185739 | E13: 176388 | F13: 163899 | G13: 156660 | H13: 152524 | I13: 143120
A14: 1012 | B14: 용접공 | C14: 인 | D14: 180350 | E14: 169201 | F14: 163001 | G14: 157183 | H14: 153849 | I14: 143509
... A33: 1031 | B33: 도배공 | C33: 인 | D33: 157719 | E33: 145618 | F33: 138737 | G33: 133325 | H33: 129887 | I33: 122699
A34: 1032 | B34: 연마공 | C34: 인 | D34: 145883 | E34: - | F34: 135816 | G34: 129000 | H34: 126629 | I34: 121211
A35: 1033 | B35: 석공 | C35: 인 | D35: 190800 | E35: 173847 | F35: 168680 | G35: 162796 | H35: 157965 | I35: 151583
A36: 1034 | B36: 줄눈공 | C36: 인 | D36: 134900 | E36: 126890 | F36: 126210 | G36: 121906 | H36: 117880 | I36: 114424
A37: 1035 | B37: 판넬조립공 | C37: 인 | D37: 160436 | E37: 152318 | F37: 146994 | G37: 141394 | H37: 137435 | I37: 132250
A38: 1036 | B38: 지붕잇기공 | C38: 인 | D38: 155527 | E38: 155855 | F38: 150969 | G38: 144009 | H38: 141063 | I38: 133189
A39: 1037 | B39: 벌목공 | C39: 인 | D39: 162884 | E39: - | F39: 153571 | G39: 144976 | H39: 139681 | I39: 133882
A40: 1038 | B40: 조경공 | C40: 인 | D40: 159410 | E40: 147733 | F40: 147748 | G40: 143852 | H40: 137988 | I40: 135114
A41: 1039 | B41: 배관공 | C41: 인 | D41: 163004 | E41: 148689 | F41: 143420 | G41: 137910 | H41: 134427 | I41: 125901
A42: 1040 | B42: 배관공(수도) | C42: 인 | D42: 177266 | E42: 163848 | F42: 158481 | G42: 149515 | H42: 143391 | I42: 140704
A43: 1041 | B43: 보일러공 | C43: 인 | D43: 159406 | E43: 147079 | F43: 142144 | G43: 136450 | H43: 130838 | I43: 125520
A44: 1042 | B44: 위생공 | C44: 인 | D44: 153392 | E44: 141618 | F44: 136613 | G44: 131450 | H44: 126225 | I44: 121038
A45: 1043 | B45: 덕트공 | C45: 인 | D45: 147452 | E45: 137653 | F45: 130860 | G45: 126874 | H45: 122054 | I45: 116121
A46: 1044 | B46: 보온공 | C46: 인 | D46: 147179 | E46: 133195 | F46: 127821 | G46: 123174 | H46: 118712 | I46: 112777
A47: 1045 | B47: 인력운반공 | C47: 인 | D47: 131775 | E47: 124911 | F47: 120074 | G47: 113766 | H47: 110197 | I47: 104748
A48: 1046 | B48: 궤도공 | C48: 인 | D48: 140101 | E48: 130850 | F48: 125226 | G48: 121380 | H48: 118155 | I48: 110698
A49: 1047 | B49: 건설기계조장 | C49: 인 | D49: 150798 | E49: 138494 | F49: 131364 | G49: 126645 | H49: 122763 | I49: 113244
A50: 1048 | B50: 건설기계운전사 | C50: 인 | D50: 181074 | E50: 162022 | F50: 154499 | G50: 148613 | H50: 143601 | I50: 135644
A51: 1049 | B51: 화물차운전사 | C51: 인 | D51: 149306 | E51: 138151 | F51: 133521 | G51: 128673 | H51: 125031 | I51: 122499
... A53: 1051 | B53: 기계설비공 | C53: 인 | D53: 153426 | E53: 145131 | F53: 140008 | G53: 135407 | H53: 131319 | I53: 124953
A54: 1052 | B54: 준설선선장 | C54: 인 | D54: 149178 | E54: - | F54: 136571 | G54: 131924 | H54: - | I54: -
A55: 1053 | B55: 준설선기관사 | C55: 인 | D55: 141301 | E55: - | F55: 129869 | G55: 125150 | H55: - | I55: -
A56: 1054 | B56: 준설선운전사 | C56: 인 | D56: 126892 | E56: 119424 | F56: - | G56: 112007 | H56: - | I56: -
A57: 1055 | B57: 선원 | C57: 인 | D57: 125707 | E57: 118553 | F57: 114850 | G57: 110424 | H57: - | I57: 108000
A58: 1056 | B58: 플랜트배관공 | C58: 인 | D58: 240654 | E58: 227813 | F58: 234786 | G58: 236621 | H58: 228165 | I58: 215183
A59: 1057 | B59: 플랜트제관공 | C59: 인 | D59: 208835 | E59: 202953 | F59: 193931 | G59: 194858 | H59: 186570 | I59: 181919
...
