Workbook

Sheet 원가계산서(총체및1차)
B1: 공 사 원 가 계 산 서
B2: 공사명 : 부산역 4층(부고열소) 내부개수 기타공사(총체)
B3: 비 목 | E3: 총체 금액 | F3: 1차 금액 | G3: 2차 금액 | H3: 구 성 비 | I3: 비 고
A4: A1 | B4: 순 공 사 원 가 | C4: 재 료 비 | D4: 직 접 재 료 비 | E4: ='원가계산서(총체)'!E4 -> 0 | F4: ='원가계산서(1차)'!E4 -> 0 | G4: =E4-F4 -> 0
A5: A2 | D5: 간 접 재 료 비 | E5: 0 | F5: 0 | G5: =E5-F5 -> 0
A6: A3 | D6: 작 업 부 산 물 | E6: ='원가계산서(총체)'!E6 -> 0 | F6: ='원가계산서(1차)'!E6 -> 0 | G6: =E6-F6 -> 0
A7: AS | D7: [ 소 계 ] | E7: =TRUNC(E4+E5-E6, 0) -> 0 | F7: =TRUNC(F4+F5-F6, 0) -> 0 | G7: =E7-F7 -> 0
A8: B1 | C8: 노 무 비 | D8: 직 접 노 무 비 | E8: ='원가계산서(총체)'!E8 -> 0 | F8: ='원가계산서(1차)'!E8 -> 0 | G8: =E8-F8 -> 0
A9: B2 | D9: 간 접 노 무 비 | E9: =TRUNC(E8*0.122, 0) -> 0 | F9: =TRUNC(F8*0.122, 0) -> 0 | G9: =E9-F9 -> 0 | H9: 직접노무비 * 12.2%
A10: BS | D10: [ 소 계 ] | E10: =TRUNC(E8+E9, 0) -> 0 | F10: =TRUNC(F8+F9, 0) -> 0 | G10: =E10-F10 -> 0
A11: C2 | C11: 경 비 | D11: 경 비 | E11: ='원가계산서(총체)'!E11 -> 0 | F11: ='원가계산서(1차)'!E11 -> 0 | G11: =E11-F11 -> 0
A12: C4 | D12: 산 재 보 험 료 | E12: =TRUNC(E10*0.037, 0) -> 0 | F12: =TRUNC(F10*0.037, 0) -> 0 | G12: =E12-F12 -> 0 | H12: 노무비 * 3.7%
A13: C5 | D13: 고 용 보 험 료 | E13: =TRUNC(E10*0.0101, 0) -> 0 | F13: =TRUNC(F10*0.0101, 0) -> 0 | G13: =E13-F13 -> 0 | H13: 노무비 * 1.01%
A14: C6 | D14: 국민 건강 보험료 | E14: =TRUNC(E8*0.03545, 0) -> 0 | F14: =TRUNC(F8*0.03545, 0) -> 0 | G14: =E14-F14 -> 0 | H14: 직접노무비 * 3.545%
A15: C7 | D15: 국민 연금 보험료 | H15: 직접노무비 * 4.5%
A16: C8 | D16: 퇴직 공제 부금비 | H16: 직접노무비 * 2.3%
A17: CA | D17: 산업안전보건관리비 | H17: (재료비+직노+관급자재비) * 1.86%
A18: CB | D18: 노인장기요양보험료 | H18: 건강보험료 * 12.81%
A19: CG | D19: 기 타 경 비 | H19: (재료비+노무비) * 5.8%
A20: CH | D20: 환 경 보 전 비 | H20: (재료비+직노+경비) * 0.3%
A21: CK | D21: 하도급지급보증수수료 | H21: (재료비+직노+경비) * 0.081% | I21: 최저가대상공사
A22: CL | D22: 건설기계대여금지급보증서발급수수료 | H22: (재료비+직노+경비) * 0.07%
A23: CS | D23: [ 소 계 ]
A24: S1 | B24: 계
A25: D1 | B25: 일 반 관 리 비 | H25: 계 * 5.5%
A26: D2 | B26: 이 윤 | H26: (노무비+경비+일반관리비) * 15%
A27: D3 | B27: 사 급 자 재 비
A28: D4 | B28: 폐기물처리비
A29: D9 | B29: 공 급 가 액
A30: DB | B30: 부 가 가 치 세 | H30: 공급가액 * 10%
A31: DH | B31: 도 급 액
A32: S2 | B32: 총 공 사 비

Sheet 원가계산서(총체)
B1: 공 사 원 가 계 산 서
B2: 공사명 : 부산역 4층(부고열소) 내부개수 기타공사(총체)
B3: 비 목 | E3: 금 액 | F3: 구 성 비 | G3: 비 고
A4: A1 | B4: 순 공 사 원 가 | C4: 재 료 비 | D4: 직 접 재 료 비 | E4: =TRUNC('공종별집계표(총체)'!F5, 0) -> 0
A5: A2 | D5: 간 접 재 료 비 | E5: 0
A6: A3 | D6: 작 업 부 산 물 | E6: =TRUNC('공종별집계표(총체)'!T18, 0) -> 0
A7: AS | D7: [ 소 계 ] | E7: =TRUNC(E4+E5-E6, 0) -> 0
A8: B1 | C8: 노 무 비 | D8: 직 접 노 무 비 | E8: =TRUNC('공종별집계표(총체)'!H5, 0) -> 0
A9: B2 | D9: 간 접 노 무 비 | E9: =TRUNC(E8*0.122, 0) -> 0 | F9: 직접노무비 * 12.2%
A10: BS | D10: [ 소 계 ] | E10: =TRUNC(E8+E9, 0) -> 0
A11: C2 | C11: 경 비 | D11: 경 비 | E11: =TRUNC('공종별집계표(총체)'!J5, 0) -> 0
A12: C4 | D12: 산 재 보 험 료 | E12: =TRUNC(E10*0.037, 0) -> 0 | F12: 노무비 * 3.7%
A13: C5 | D13: 고 용 보 험 료 | E13: =TRUNC(E10*0.0101, 0) -> 0 | F13: 노무비 * 1.01%
A14: C6 | D14: 국민 건강 보험료 | E14: =TRUNC(E8*0.03545, 0) -> 0 | F14: 직접노무비 * 3.545%
A15: C7 | D15: 국민 연금 보험료 | E15: =TRUNC(E8*0.045, 0) -> 0 | F15: 직접노무비 * 4.5%
A16: C8 | D16: 퇴직 공제 부금비 | E16: =TRUNC(E8*0.023, 0) -> 0 | F16: 직접노무비 * 2.3%
A17: CA | D17: 산업안전보건관리비 | F17: (재료비+직노+관급자재비) * 1.86%
A18: CB | D18: 노인장기요양보험료 | F18: 건강보험료 * 12.81%
A19: CG | D19: 기 타 경 비 | F19: (재료비+노무비) * 5.8%
A20: CH | D20: 환 경 보 전 비 | F20: (재료비+직노+경비) * 0.3%
A21: CK | D21: 하도급지급보증수수료 | F21: (재료비+직노+경비) * 0.081% | G21: 최저가대상공사
A22: CL | D22: 건설기계대여금지급보증서발급수수료 | F22: (재료비+직노+경비) * 0.07%
A23: CS | D23: [ 소 계 ]
A24: S1 | B24: 계
A25: D1 | B25: 일 반 관 리 비 | F25: 계 * 5.5%
A26: D2 | B26: 이 윤 | F26: (노무비+경비+일반관리비) * 15%
A27: D3 | B27: 사 급 자 재 비
A28: D4 | B28: 폐기물처리비
A29: D9 | B29: 공 급 가 액
A30: DB | B30: 부 가 가 치 세 | F30: 공급가액 * 10%
A31: DH | B31: 도 급 액
A32: S2 | B32: 총 공 사 비

Sheet 원가계산서(1차)
B1: 공 사 원 가 계 산 서
B2: 공사명 : 부산역 4층(부고열소) 내부개수 기타공사(1차) | F2: 금액 : 오억오천일백육십오만원(￦551,650,000)
B3: 비 목 | E3: 금 액 | F3: 구 성 비 | G3: 비 고
A4: A1 | B4: 순 공 사 원 가 | C4: 재 료 비 | D4: 직 접 재 료 비
A5: A2 | D5: 간 접 재 료 비
A6: A3 | D6: 작 업 부 산 물
A7: AS | D7: [ 소 계 ]
A8: B1 | C8: 노 무 비 | D8: 직 접 노 무 비
A9: B2 | D9: 간 접 노 무 비 | F9: 직접노무비 * 12.2%
A10: BS | D10: [ 소 계 ]
A11: C2 | C11: 경 비 | D11: 경 비
A12: C4 | D12: 산 재 보 험 료 | F12: 노무비 * 3.7%
A13: C5 | D13: 고 용 보 험 료 | F13: 노무비 * 1.01%
A14: C6 | D14: 국민 건강 보험료 | F14: 직접노무비 * 3.545%
A15: C7 | D15: 국민 연금 보험료 | F15: 직접노무비 * 4.5%
A16: C8 | D16: 퇴직 공제 부금비 | F16: 직접노무비 * 2.3%
A17: CA | D17: 산업안전보건관리비 | F17: (재료비+직노+관급자재비) * 1.86%
A18: CB | D18: 노인장기요양보험료 | F18: 건강보험료 * 12.81%
A19: CG | D19: 기 타 경 비 | F19: (재료비+노무비) * 5.8%
A20: CH | D20: 환 경 보 전 비 | F20: (재료비+직노+경비) * 0.3%
A21: CK | D21: 하도급지급보증수수료 | F21: (재료비+직노+경비) * 0.081% | G21: 최저가대상공사
A22: CL | D22: 건설기계대여금지급보증서발급수수료 | F22: (재료비+직노+경비) * 0.07%
A23: CS | D23: [ 소 계 ]
A24: S1 | B24: 계
A25: D1 | B25: 일 반 관 리 비 | F25: 계 * 5.5%
A26: D2 | B26: 이 윤 | F26: (노무비+경비+일반관리비) * 15%
A27: D3 | B27: 사 급 자 재 비
A28: D9 | B28: 공 급 가 액
A29: DB | B29: 부 가 가 치 세 | F29: 공급가액 * 10%
A30: DH | B30: 도 급 액
A31: S2 | B31: 총 공 사 비

Sheet 공종별집계표(총체)
A1: 공 종 별 집 계 표
A2: [ 부산역 4층(부고열소) 내부개수 기타공사(총체) ]
A3: 품 명 | B3: 규 격 | C3: 단위 | D3: 수량 | E3: 재 료 비 | G3: 노 무 비 | I3: 경 비 | K3: 합 계 | M3: 비 고 | N3: 공종코드 | O3: 변수 | P3: 상위공종 | Q3: 공종구분 | R3: 공종레벨 | S3: 공종소계 | T3: 원가계산서 연결금액
E4: 단 가 | F4: 금 액 | G4: 단 가 | H4: 금 액 | I4: 단 가 | J4: 금 액 | K4: 단 가 | L4: 금 액
A5: 01 부산역 4층(부고열소) 내부개수 기타공사(총체) | D5: 1 | E5: =F6+F7+F8+F9+F10+F11+F12+F13+F14+F15+F16 -> 0 | F5: =E5*D5 -> 0 | G5: =H6+H7+H8+H9+H10+H11+H12+H13+H14+H15+H16 -> 0 | H5: =G5*D5 -> 0 | I5: =J6+J7+J8+J9+J10+J11+J12+J13+J14+J15+J16 -> 0 | J5: =I5*D5 -> 0 | K5: =E5+G5+I5 -> 0 | L5: =F5+H5+J5 -> 0 | N5: 01 | R5: 1
A6: 0101 가설공사 | D6: 1 | E6: ='공종별내역서(총체)'!F25 -> 0 | F6: =E6*D6 -> 0 | G6: ='공종별내역서(총체)'!H25 -> 0 | H6: =G6*D6 -> 0 | I6: ='공종별내역서(총체)'!J25 -> 0 | J6: =I6*D6 -> 0 | K6: =E6+G6+I6 -> 0 | L6: =F6+H6+J6 -> 0 | N6: 0101 | P6: 01 | R6: 2
A7: 0102 조적공사 및 미장공사 | D7: 1 | E7: ='공종별내역서(총체)'!F47 -> 0 | F7: =E7*D7 -> 0 | G7: ='공종별내역서(총체)'!H47 -> 0 | H7: =G7*D7 -> 0 | I7: ='공종별내역서(총체)'!J47 -> 0 | J7: =I7*D7 -> 0 | K7: =E7+G7+I7 -> 0 | L7: =F7+H7+J7 -> 0 | N7: 0102 | P7: 01 | R7: 2
A8: 0103 타일공사 및 방수공사 | D8: 1 | E8: ='공종별내역서(총체)'!F69 -> 0 | F8: =E8*D8 -> 0 | G8: ='공종별내역서(총체)'!H69 -> 0 | H8: =G8*D8 -> 0 | I8: ='공종별내역서(총체)'!J69 -> 0 | J8: =I8*D8 -> 0 | K8: =E8+G8+I8 -> 0 | L8: =F8+H8+J8 -> 0 | N8: 0103 | P8: 01 | R8: 2
A9: 0104 목공사 및 수장공사 | D9: 1 | E9: ='공종별내역서(총체)'!F135 -> 0 | F9: =E9*D9 -> 0 | G9: ='공종별내역서(총체)'!H135 -> 0 | H9: =G9*D9 -> 0 | I9: ='공종별내역서(총체)'!J135 -> 0 | J9: =I9*D9 -> 0 | K9: =E9+G9+I9 -> 0 | L9: =F9+H9+J9 -> 0 | N9: 0104 | P9: 01 | R9: 2
A10: 0105 금속공사 | D10: 1 | E10: ='공종별내역서(총체)'!F157 -> 0 | F10: =E10*D10 -> 0 | G10: ='공종별내역서(총체)'!H157 -> 0 | H10: =G10*D10 -> 0 | I10: ='공종별내역서(총체)'!J157 -> 0 | J10: =I10*D10 -> 0 | K10: =E10+G10+I10 -> 0 | L10: =F10+H10+J10 -> 0 | N10: 0105 | P10: 01 | R10: 2
A11: 0106 창호공사 | D11: 1 | E11: ='공종별내역서(총체)'!F179 -> 0 | F11: =E11*D11 -> 0 | G11: ='공종별내역서(총체)'!H179 -> 0 | H11: =G11*D11 -> 0 | I11: ='공종별내역서(총체)'!J179 -> 0 | J11: =I11*D11 -> 0 | K11: =E11+G11+I11 -> 0 | L11: =F11+H11+J11 -> 0 | N11: 0106 | P11: 01 | R11: 2
A12: 0107 칠공사 | D12: 1 | E12: ='공종별내역서(총체)'!F201 -> 0 | F12: =E12*D12 -> 0 | G12: ='공종별내역서(총체)'!H201 -> 0 | H12: =G12*D12 -> 0 | I12: ='공종별내역서(총체)'!J201 -> 0 | J12: =I12*D12 -> 0 | K12: =E12+G12+I12 -> 0 | L12: =F12+H12+J12 -> 0 | N12: 0107 | P12: 01 | R12: 2
A13: 0108 급수·위생설비공사 | D13: 1 | E13: ='공종별내역서(총체)'!F267 -> 0 | F13: =E13*D13 -> 0 | G13: ='공종별내역서(총체)'!H267 -> 0 | H13: =G13*D13 -> 0 | I13: ='공종별내역서(총체)'!J267 -> 0 | J13: =I13*D13 -> 0 | K13: =E13+G13+I13 -> 0 | L13: =F13+H13+J13 -> 0 | N13: 0108 | P13: 01 | R13: 2
A14: 0109 공기조화설비공사 | D14: 1 | E14: ='공종별내역서(총체)'!F289 -> 0 | F14: =E14*D14 -> 0 | G14: ='공종별내역서(총체)'!H289 -> 0 | H14: =G14*D14 -> 0 | I14: ='공종별내역서(총체)'!J289 -> 0 | J14: =I14*D14 -> 0 | K14: =E14+G14+I14 -> 0 | L14: =F14+H14+J14 -> 0 | N14: 0109 | P14: 01 | R14: 2
A15: 0110 부대공사 | D15: 1 | E15: ='공종별내역서(총체)'!F311 -> 0 | F15: =E15*D15 -> 0 | G15: ='공종별내역서(총체)'!H311 -> 0 | H15: =G15*D15 -> 0 | I15: ='공종별내역서(총체)'!J311 -> 0 | J15: =I15*D15 -> 0 | K15: =E15+G15+I15 -> 0 | L15: =F15+H15+J15 -> 0 | N15: 0110 | P15: 01 | R15: 2
A16: 0111 철거공사 | D16: 1 | E16: ='공종별내역서(총체)'!F333 -> 0 | F16: =E16*D16 -> 0 | G16: ='공종별내역서(총체)'!H333 -> 0 | H16: =G16*D16 -> 0 | I16: ='공종별내역서(총체)'!J333 -> 0 | J16: =I16*D16 -> 0 | K16: =E16+G16+I16 -> 0 | L16: =F16+H16+J16 -> 0 | N16: 0111 | P16: 01 | R16: 2
A17: 0112 폐기물처리비 | D17: 1 | E17: ='공종별내역서(총체)'!F355 -> 0 | F17: =E17*D17 -> 0 | G17: ='공종별내역서(총체)'!H355 -> 0 | H17: =G17*D17 -> 0 | I17: ='공종별내역서(총체)'!J355 -> 0 | J17: =I17*D17 -> 0 | K17: =E17+G17+I17 -> 0 | L17: =F17+H17+J17 -> 0 | N17: 0112 | Q17: 6 | R17: 2 | T17: =L17*1 -> 0
A18: 0113 작업부산물 | D18: 1 | E18: ='공종별내역서(총체)'!F377 -> 0 | F18: =E18*D18 -> 0 | G18: ='공종별내역서(총체)'!H377 -> 0 | H18: =G18*D18 -> 0 | I18: ='공종별내역서(총체)'!J377 -> 0 | J18: =I18*D18 -> 0 | K18: =E18+G18+I18 -> 0 | L18: =F18+H18+J18 -> 0 | N18: 0113 | Q18: 1 | R18: 2 | T18: =L18*1 -> 0
A19: 0114 사급자재비 | D19: 1 | E19: ='공종별내역서(총체)'!F399 -> 0 | F19: =E19*D19 -> 0 | G19: ='공종별내역서(총체)'!H399 -> 0 | H19: =G19*D19 -> 0 | I19: ='공종별내역서(총체)'!J399 -> 0 | J19: =I19*D19 -> 0 | K19: =E19+G19+I19 -> 0 | L19: =F19+H19+J19 -> 0 | N19: 0114 | Q19: 4 | R19: 2 | T19: =L19*1 -> 0
A25: [ 합 계 ] | F25: =F5 -> 0 | H25: =H5 -> 0 | J25: =J5 -> 0 | L25: =L5 -> 0

Sheet 공종별내역서(총체)
A1: [ 부산역 4층(부고열소) 내부개수 기타공사(총체) ]
A2: 품 명 | B2: 규 격 | C2: 단위 | D2: 수량 | E2: 재 료 비 | G2: 노 무 비 | I2: 경 비 | K2: 합 계 | M2: 비 고 | N2: 품목코드 | O2: 변수 | P2: 설정 | Q2: 공종코드 | R2: 일위 | S2: 단산 | T2: 자재 | U2: 손료적용 | V2: 손료저장 | W2: 적용율 | X2: JUK1 | Y2: JUK2 | Z2: JUK3 | AA2: JUK4 | AB2: JUK5 | AC2: JUK6 | AD2: JUK7 | AE2: JUK8 | AF2: JUK9 | AG2: JUK10 | AH2: JUK11 | AI2: JUK12 | AJ2: JUK13 | AK2: JUK14 | AL2: JUK15 | AM2: JUK16 | AN2: JUK17 | AO2: JUK18 | AP2: JUK19 | AQ2: JUK20 | AR2: 자재구분 | AS2: 공종구분 | AT2: 공종레벨 | AU2: 공종+자재 | AV2: 고유번호
E3: 단 가 | F3: 금 액 | G3: 단 가 | H3: 금 액 | I3: 단 가 | J3: 금 액 | K3: 단 가 | L3: 금 액
A4: 0101 가설공사 | Q4: 0101
A5: 콘테이너형 가설사무소 설치 및 해체 | B5: 3.0*6.0m, 3개월 | C5: 개소 | D5: 3 | E5: =TRUNC('일위대가목록(총체)'!E4,0) -> 0 | F5: =TRUNC(E5*D5, 0) -> 0 | G5: =TRUNC('일위대가목록(총체)'!F4,0) -> 0 | H5: =TRUNC(G5*D5, 0) -> 0 | I5: =TRUNC('일위대가목록(총체)'!G4,0) -> 0 | J5: =TRUNC(I5*D5, 0) -> 0 | K5: =TRUNC(E5+G5+I5, 0) -> 0 | L5: =TRUNC(F5+H5+J5, 0) -> 0 | N5: 528CE206FA04C98EB34FCA3743B093 | Q5: 0101 | R5: T | S5: F | T5: F | AU5: 0101528CE206FA04C98EB34FCA3743B093 | AV5: 3
A6: 콘테이너형 가설창고 설치 및 해체 | B6: 3.0*6.0m, 3개월 | C6: 개소 | D6: 1 | E6: =TRUNC('일위대가목록(총체)'!E5,0) -> 0 | F6: =TRUNC(E6*D6, 0) -> 0 | G6: =TRUNC('일위대가목록(총체)'!F5,0) -> 0 | H6: =TRUNC(G6*D6, 0) -> 0 | I6: =TRUNC('일위대가목록(총체)'!G5,0) -> 0 | J6: =TRUNC(I6*D6, 0) -> 0 | K6: =TRUNC(E6+G6+I6, 0) -> 0 | L6: =TRUNC(F6+H6+J6, 0) -> 0 | N6: 528CE206FA04F95DAB2BC23B235ECF | Q6: 0101 | R6: T | S6: F | T6: F | AU6: 0101528CE206FA04F95DAB2BC23B235ECF | AV6: 4
A7: 건축물 현장정리 | B7: 목조, 철골조, 조적조 | C7: M2 | D7: 245 | E7: =TRUNC('일위대가목록(총체)'!E6,0) -> 0 | F7: =TRUNC(E7*D7, 0) -> 0 | G7: =TRUNC('일위대가목록(총체)'!F6,0) -> 0 | H7: =TRUNC(G7*D7, 0) -> 0 | I7: =TRUNC('일위대가목록(총체)'!G6,0) -> 0 | J7: =TRUNC(I7*D7, 0) -> 0 | K7: =TRUNC(E7+G7+I7, 0) -> 0 | L7: =TRUNC(F7+H7+J7, 0) -> 0 | N7: 528CE20691B3B972B985053583A21F | Q7: 0101 | R7: T | S7: F | T7: F | AU7: 0101528CE20691B3B972B985053583A21F | AV7: 5
A8: 강관 조립말비계(이동식)설치 및 해체 | B8: 높이 4m, 3개월 | C8: 대 | D8: 2 | E8: =TRUNC('일위대가목록(총체)'!E7,0) -> 0 | F8: =TRUNC(E8*D8, 0) -> 0 | G8: =TRUNC('일위대가목록(총체)'!F7,0) -> 0 | H8: =TRUNC(G8*D8, 0) -> 0 | I8: =TRUNC('일위대가목록(총체)'!G7,0) -> 0 | J8: =TRUNC(I8*D8, 0) -> 0 | K8: =TRUNC(E8+G8+I8, 0) -> 0 | L8: =TRUNC(F8+H8+J8, 0) -> 0 | N8: 528CE206CEDAC9860073CE3B53545E | Q8: 0101 | R8: T | S8: F | T8: F | AU8: 0101528CE206CEDAC9860073CE3B53545E | AV8: 6
A9: 시스템비계 설치 및 해체 | B9: 10m 이하 | C9: M2 | D9: 336 | E9: =TRUNC('일위대가목록(총체)'!E8,0) -> 0 | F9: =TRUNC(E9*D9, 0) -> 0 | G9: =TRUNC('일위대가목록(총체)'!F8,0) -> 0 | H9: =TRUNC(G9*D9, 0) -> 0 | I9: =TRUNC('일위대가목록(총체)'!G8,0) -> 0 | J9: =TRUNC(I9*D9, 0) -> 0 | K9: =TRUNC(E9+G9+I9, 0) -> 0 | L9: =TRUNC(F9+H9+J9, 0) -> 0 | N9: 528CE206CEDAC98602247D3B532581 | Q9: 0101 | R9: T | S9: F | T9: F | AU9: 0101528CE206CEDAC98602247D3B532581 | AV9: 7
A10: RPP가설울타리판 설치 | B10: 설치높이 6m 이하 | C10: M | D10: 145 | E10: =TRUNC('일위대가목록(총체)'!E9,0) -> 0 | F10: =TRUNC(E10*D10, 0) -> 0 | G10: =TRUNC('일위대가목록(총체)'!F9,0) -> 0 | H10: =TRUNC(G10*D10, 0) -> 0 | I10: =TRUNC('일위대가목록(총체)'!G9,0) -> 0 | J10: =TRUNC(I10*D10, 0) -> 0 | K10: =TRUNC(E10+G10+I10, 0) -> 0 | L10: =TRUNC(F10+H10+J10, 0) -> 0 | N10: 528CE206CEF5C913FD184B3B537AB61C | Q10: 0101 | R10: T | S10: F | T10: F | AU10: 0101528CE206CEF5C913FD184B3B537AB61C | AV10: 100
A11: RPP 가설흡음형 방음판 | B11: H-667*40T | C11: ㎡ | D11: 593 | E11: =TRUNC('단가대비표(총체)'!O35,0) -> 0 | F11: =TRUNC(E11*D11, 0) -> 0 | G11: =TRUNC('단가대비표(총체)'!P35,0) -> 0 | H11: =TRUNC(G11*D11, 0) -> 0 | I11: =TRUNC('단가대비표(총체)'!V35,0) -> 0 | J11: =TRUNC(I11*D11, 0) -> 0 | K11: =TRUNC(E11+G11+I11, 0) -> 0 | L11: =TRUNC(F11+H11+J11, 0) -> 0 | N11: 55A91276F33FC9B81C1B63395392CE628CD7387C | Q11: 0101 | R11: F | S11: F | T11: T | AU11: 010155A91276F33FC9B81C1B63395392CE628CD7387C | AV11: 102
A12: RPP가설울타리판 해체 | B12: 설치높이 6m 이하 | C12: M | D12: 145 | E12: =TRUNC('일위대가목록(총체)'!E10,0) -> 0 | F12: =TRUNC(E12*D12, 0) -> 0 | G12: =TRUNC('일위대가목록(총체)'!F10,0) -> 0 | H12: =TRUNC(G12*D12, 0) -> 0 | I12: =TRUNC('일위대가목록(총체)'!G10,0) -> 0 | J12: =TRUNC(I12*D12, 0) -> 0 | K12: =TRUNC(E12+G12+I12, 0) -> 0 | L12: =TRUNC(F12+H12+J12, 0) -> 0 | N12: 528CE206CEF5C913FD184B3B537B5CE1 | Q12: 0101 | R12: T | S12: F | T12: F | AU12: 0101528CE206CEF5C913FD184B3B537B5CE1 | AV12: 101
A25: [ 합 계 ] | F25: =SUM(F5:F24) -> 0 | H25: =SUM(H5:H24) -> 0 | J25: =SUM(J5:J24) -> 0 | L25: =SUM(L5:L24) -> 0 | N25: TOTAL
A26: 0102 조적공사 및 미장공사 | Q26: 0102
A27: 1.0B 벽돌쌓기 | B27: 3.6m 초과 | C27: M2 | D27: 228 | E27: =TRUNC('일위대가목록(총체)'!E11,0) -> 0 | F27: =TRUNC(E27*D27, 0) -> 0 | G27: =TRUNC('일위대가목록(총체)'!F11,0) -> 0 | H27: =TRUNC(G27*D27, 0) -> 0 | I27: =TRUNC('일위대가목록(총체)'!G11,0) -> 0 | J27: =TRUNC(I27*D27, 0) -> 0 | K27: =TRUNC(E27+G27+I27, 0) -> 0 | L27: =TRUNC(F27+H27+J27, 0) -> 0 | N27: 528C9286A920C9AA1212993083EF9B | Q27: 0102 | R27: T | S27: F | T27: F | AU27: 0102528C9286A920C9AA1212993083EF9B | AV27: 10
A28: 콘크리트벽돌 | B28: 콘크리트벽돌, 190*57*90mm, 부산, C종2급 | C28: 매 | D28: 34689 | E28: =TRUNC('단가대비표(총체)'!O36,0) -> 0 | F28: =TRUNC(E28*D28, 0) -> 0 | G28: =TRUNC('단가대비표(총체)'!P36,0) -> 0 | H28: =TRUNC(G28*D28, 0) -> 0 | I28: =TRUNC('단가대비표(총체)'!V36,0) -> 0 | J28: =TRUNC(I28*D28, 0) -> 0 | K28: =TRUNC(E28+G28+I28, 0) -> 0 | L28: =TRUNC(F28+H28+J28, 0) -> 0 | N28: 55A91276F32D69BA3EC34E3DC3FEFBFD509264 | Q28: 0102 | R28: F | S28: F | T28: T | AU28: 010255A91276F32D69BA3EC34E3DC3FEFBFD509264 | AV28: 11
A29: 벽돌운반 | B29: 인력, 4층 | C29: 천매 | D29: 35.441 | E29: =TRUNC('일위대가목록(총체)'!E12,0) -> 0 | F29: =TRUNC(E29*D29, 0) -> 0 | G29: =TRUNC('일위대가목록(총체)'!F12,0) -> 0 | H29: =TRUNC(G29*D29, 0) -> 0 | I29: =TRUNC('일위대가목록(총체)'!G12,0) -> 0 | J29: =TRUNC(I29*D29, 0) -> 0 | K29: =TRUNC(E29+G29+I29, 0) -> 0 | L29: =TRUNC(F29+H29+J29, 0) -> 0 | N29: 528C9286A90419EA3F99A93D539B80 | Q29: 0102 | R29: T | S29: F | T29: F | AU29: 0102528C9286A90419EA3F99A93D539B80 | AV29: 12
A30: 모르타르 바름 | B30: 내벽, 18mm, 3.6m 초과 | C30: M2 | D30: 451 | E30: =TRUNC('일위대가목록(총체)'!E13,0) -> 0 | F30: =TRUNC(E30*D30, 0) -> 0 | G30: =TRUNC('일위대가목록(총체)'!F13,0) -> 0 | H30: =TRUNC(G30*D30, 0) -> 0 | I30: =TRUNC('일위대가목록(총체)'!G13,0) -> 0 | J30: =TRUNC(I30*D30, 0) -> 0 | K30: =TRUNC(E30+G30+I30, 0) -> 0 | L30: =TRUNC(F30+H30+J30, 0) -> 0 | N30: 528C82A6506BD9409745C83ED332CF | Q30: 0102 | R30: T | S30: F | T30: F | AU30: 0102528C82A6506BD9409745C83ED332CF | AV30: 13
A31: 구배모르타르 바름 | B31: 바닥, 24mm | C31: M2 | D31: 54 | E31: =TRUNC('일위대가목록(총체)'!E14,0) -> 0 | F31: =TRUNC(E31*D31, 0) -> 0 | G31: =TRUNC('일위대가목록(총체)'!F14,0) -> 0 | H31: =TRUNC(G31*D31, 0) -> 0 | I31: =TRUNC('일위대가목록(총체)'!G14,0) -> 0 | J31: =TRUNC(I31*D31, 0) -> 0 | K31: =TRUNC(E31+G31+I31, 0) -> 0 | L31: =TRUNC(F31+H31+J31, 0) -> 0 | N31: 528C82A6506BF97316C7B53683AF23E0 | Q31: 0102 | R31: T | S31: F | T31: F | AU31: 0102528C82A6506BF97316C7B53683AF23E0 | AV31: 14
A32: 모르타르 바름 | B32: 바닥, 30mm | C32: M2 | D32: 40 | E32: =TRUNC('일위대가목록(총체)'!E15,0) -> 0 | F32: =TRUNC(E32*D32, 0) -> 0 | G32: =TRUNC('일위대가목록(총체)'!F15,0) -> 0 | H32: =TRUNC(G32*D32, 0) -> 0 | I32: =TRUNC('일위대가목록(총체)'!G15,0) -> 0 | J32: =TRUNC(I32*D32, 0) -> 0 | K32: =TRUNC(E32+G32+I32, 0) -> 0 | L32: =TRUNC(F32+H32+J32, 0) -> 0 | N32: 528C82A6506BF97316C7B53693B2BA | Q32: 0102 | R32: T | S32: F | T32: F | AU32: 0102528C82A6506BF97316C7B53693B2BA | AV32: 15
A33: 자동 수평 모르타르 바름 | B33: 바닥 10T | C33: M2 | D33: 662 | E33: =TRUNC('일위대가목록(총체)'!E16,0) -> 0 | F33: =TRUNC(E33*D33, 0) -> 0 | G33: =TRUNC('일위대가목록(총체)'!F16,0) -> 0 | H33: =TRUNC(G33*D33, 0) -> 0 | I33: =TRUNC('일위대가목록(총체)'!G16,0) -> 0 | J33: =TRUNC(I33*D33, 0) -> 0 | K33: =TRUNC(E33+G33+I33, 0) -> 0 | L33: =TRUNC(F33+H33+J33, 0) -> 0 | N33: 528C82A6506BF908FCCB2A3A031E5119 | Q33: 0102 | R33: T | S33: F | T33: F | AU33: 0102528C82A6506BF908FCCB2A3A031E5119 | AV33: 16
A47: [ 합 계 ] | F47: =SUM(F27:F46) -> 0 | H47: =SUM(H27:H46) -> 0 | J47: =SUM(J27:J46) -> 0 | L47: =SUM(L27:L46) -> 0 | N47: TOTAL
A48: 0103 타일공사 및 방수공사 | Q48: 0103
A49: 타일 떠붙이기(바탕 24mm) | B49: 벽, 0.11∼0.20 이하, 백색줄눈 | C49: M2 | D49: 141 | E49: =TRUNC('일위대가목록(총체)'!E17,0) -> 0 | F49: =TRUNC(E49*D49, 0) -> 0 | G49: =TRUNC('일위대가목록(총체)'!F17,0) -> 0 | H49: =TRUNC(G49*D49, 0) -> 0 | I49: =TRUNC('일위대가목록(총체)'!G17,0) -> 0 | J49: =TRUNC(I49*D49, 0) -> 0 | K49: =TRUNC(E49+G49+I49, 0) -> 0 | L49: =TRUNC(F49+H49+J49, 0) -> 0 | N49: 528C2236DDB5A9868959173153EBC0 | Q49: 0103 | R49: T | S49: F | T49: F | AU49: 0103528C2236DDB5A9868959173153EBC0 | AV49: 18
A50: 타일 압착 붙이기(바탕 12mm+압 5mm) | B50: 바닥, 300*300(타일C, 백색줄눈) | C50: M2 | D50: 57 | E50: =TRUNC('일위대가목록(총체)'!E18,0) -> 0 | F50: =TRUNC(E50*D50, 0) -> 0 | G50: =TRUNC('일위대가목록(총체)'!F18,0) -> 0 | H50: =TRUNC(G50*D50, 0) -> 0 | I50: =TRUNC('일위대가목록(총체)'!G18,0) -> 0 | J50: =TRUNC(I50*D50, 0) -> 0 | K50: =TRUNC(E50+G50+I50, 0) -> 0 | L50: =TRUNC(F50+H50+J50, 0) -> 0 | N50: 528C2236DD9AF9FF62219F3BB320A3 | Q50: 0103 | R50: T | S50: F | T50: F | AU50: 0103528C2236DD9AF9FF62219F3BB320A3 | AV50: 19
A51: 화강석 두겁돌(습식, 물갈기) | B51: 창대, 마천석 120*30mm, 모르타르 30mm | C51: M | D51: 9 | E51: =TRUNC('일위대가목록(총체)'!E19,0) -> 0 | F51: =TRUNC(E51*D51, 0) -> 0 | G51: =TRUNC('일위대가목록(총체)'!F19,0) -> 0 | H51: =TRUNC(G51*D51, 0) -> 0 | I51: =TRUNC('일위대가목록(총체)'!G19,0) -> 0 | J51: =TRUNC(I51*D51, 0) -> 0 | K51: =TRUNC(E51+G51+I51, 0) -> 0 | L51: =TRUNC(F51+H51+J51, 0) -> 0 | N51: 528C2236EE62B987D089DD3563E2B14D | Q51: 0103 | R51: T | S51: F | T51: F | AU51: 0103528C2236EE62B987D089DD3563E2B14D | AV51: 40
A52: 도기질타일 | B52: 도기질타일, 일반색, 300*600*10mm | C52: M2 | D52: 146 | E52: =TRUNC('단가대비표(총체)'!O38,0) -> 0 | F52: =TRUNC(E52*D52, 0) -> 0 | G52: =TRUNC('단가대비표(총체)'!P38,0) -> 0 | H52: =TRUNC(G52*D52, 0) -> 0 | I52: =TRUNC('단가대비표(총체)'!V38,0) -> 0 | J52: =TRUNC(I52*D52, 0) -> 0 | K52: =TRUNC(E52+G52+I52, 0) -> 0 | L52: =TRUNC(F52+H52+J52, 0) -> 0 | N52: 55A91276F32D69BBC555DF33D3A2DB45AA928F | Q52: 0103 | R52: F | S52: F | T52: T | AU52: 010355A91276F32D69BBC555DF33D3A2DB45AA928F | AV52: 20
A53: 자기질타일 | B53: 자기질타일, 시유, 300*300*8mm | C53: M2 | D53: 59 | E53: =TRUNC('단가대비표(총체)'!O39,0) -> 0 | F53: =TRUNC(E53*D53, 0) -> 0 | G53: =TRUNC('단가대비표(총체)'!P39,0) -> 0 | H53: =TRUNC(G53*D53, 0) -> 0 | I53: =TRUNC('단가대비표(총체)'!V39,0) -> 0 | J53: =TRUNC(I53*D53, 0) -> 0 | K53: =TRUNC(E53+G53+I53, 0) -> 0 | L53: =TRUNC(F53+H53+J53, 0) -> 0 | N53: 55A91276F32D69BBC555DF33F35D08EE3EEC56 | Q53: 0103 | R53: F | S53: F | T53: T | AU53: 010355A91276F32D69BBC555DF33F35D08EE3EEC56 | AV53: 21
A54: 수용성 고무화 아스팔트방수 | B54: 바닥, 비노출 | C54: M2 | D54: 54 | E54: =TRUNC('일위대가목록(총체)'!E20,0) -> 0 | F54: =TRUNC(E54*D54, 0) -> 0 | G54: =TRUNC('일위대가목록(총체)'!F20,0) -> 0 | H54: =TRUNC(G54*D54, 0) -> 0 | I54: =TRUNC('일위대가목록(총체)'!G20,0) -> 0 | J54: =TRUNC(I54*D54, 0) -> 0 | K54: =TRUNC(E54+G54+I54, 0) -> 0 | L54: =TRUNC(F54+H54+J54, 0) -> 0 | N54: 528C72B6D26AD9C653490E35E304BB | Q54: 0103 | R54: T | S54: F | T54: F | AU54: 0103528C72B6D26AD9C653490E35E304BB | AV54: 22
A55: 수용성 고무화 아스팔트방수 | B55: 벽, 비노출 | C55: M2 | D55: 14 | E55: =TRUNC('일위대가목록(총체)'!E21,0) -> 0 | F55: =TRUNC(E55*D55, 0) -> 0 | G55: =TRUNC('일위대가목록(총체)'!F21,0) -> 0 | H55: =TRUNC(G55*D55, 0) -> 0 | I55: =TRUNC('일위대가목록(총체)'!G21,0) -> 0 | J55: =TRUNC(I55*D55, 0) -> 0 | K55: =TRUNC(E55+G55+I55, 0) -> 0 | L55: =TRUNC(F55+H55+J55, 0) -> 0 | N55: 528C72B6D26AD9C653490E35E304BA | Q55: 0103 | R55: T | S55: F | T55: F | AU55: 0103528C72B6D26AD9C653490E35E304BA | AV55: 23
A56: 시멘트 액체방수 바름 | B56: 바닥 | C56: M2 | D56: 54 | E56: =TRUNC('일위대가목록(총체)'!E22,0) -> 0 | F56: =TRUNC(E56*D56, 0) -> 0 | G56: =TRUNC('일위대가목록(총체)'!F22,0) -> 0 | H56: =TRUNC(G56*D56, 0) -> 0 | I56: =TRUNC('일위대가목록(총체)'!G22,0) -> 0 | J56: =TRUNC(I56*D56, 0) -> 0 | K56: =TRUNC(E56+G56+I56, 0) -> 0 | L56: =TRUNC(F56+H56+J56, 0) -> 0 | N56: 528C72B679E069B4976E273913F293 | Q56: 0103 | R56: T | S56: F | T56: F | AU56: 0103528C72B679E069B4976E273913F293 | AV56: 24
A57: 시멘트 액체방수 바름 | B57: 벽 | C57: M2 | D57: 127 | E57: =TRUNC('일위대가목록(총체)'!E23,0) -> 0 | F57: =TRUNC(E57*D57, 0) -> 0 | G57: =TRUNC('일위대가목록(총체)'!F23,0) -> 0 | H57: =TRUNC(G57*D57, 0) -> 0 | I57: =TRUNC('일위대가목록(총체)'!G23,0) -> 0 | J57: =TRUNC(I57*D57, 0) -> 0 | K57: =TRUNC(E57+G57+I57, 0) -> 0 | L57: =TRUNC(F57+H57+J57, 0) -> 0 | N57: 528C72B679E069B4976E273913F2935C | Q57: 0103 | R57: T | S57: F | T57: F | AU57: 0103528C72B679E069B4976E273913F2935C | AV57: 26
A69: [ 합 계 ] | F69: =SUM(F49:F68) -> 0 | H69: =SUM(H49:H68) -> 0 | J69: =SUM(J49:J68) -> 0 | L69: =SUM(L49:L68) -> 0 | N69: TOTAL
A70: 0104 목공사 및 수장공사 | Q70: 0104
A71: 마루틀 설치 | B71: 45*45, @450 | C71: M2 | D71: 77 | E71: =TRUNC('일위대가목록(총체)'!E24,0) -> 0 | F71: =TRUNC(E71*D71, 0) -> 0 | G71: =TRUNC('일위대가목록(총체)'!F24,0) -> 0 | H71: =TRUNC(G71*D71, 0) -> 0 | I71: =TRUNC('일위대가목록(총체)'!G24,0) -> 0 | J71: =TRUNC(I71*D71, 0) -> 0 | K71: =TRUNC(E71+G71+I71, 0) -> 0 | L71: =TRUNC(F71+H71+J71, 0) -> 0 | N71: 528C625664E5499988B0D5373338BE | Q71: 0104 | R71: T | S71: F | T71: F | AU71: 0104528C625664E5499988B0D5373338BE | AV71: 30
A72: 마루틀 설치 | B72: 90*90, @900 | C72: M2 | D72: 77 | E72: =TRUNC('일위대가목록(총체)'!E25,0) -> 0 | F72: =TRUNC(E72*D72, 0) -> 0 | G72: =TRUNC('일위대가목록(총체)'!F25,0) -> 0 | H72: =TRUNC(G72*D72, 0) -> 0 | I72: =TRUNC('일위대가목록(총체)'!G25,0) -> 0 | J72: =TRUNC(I72*D72, 0) -> 0 | K72: =TRUNC(E72+G72+I72, 0) -> 0 | L72: =TRUNC(F72+H72+J72, 0) -> 0 | N72: 528C625664E5499988B1F23193C65A | Q72: 0104 | R72: T | S72: F | T72: F | AU72: 0104528C625664E5499988B1F23193C65A | AV72: 31
A73: 마루귀틀 설치 | C73: M | D73: 24 | E73: =TRUNC('일위대가목록(총체)'!E26,0) -> 0 | F73: =TRUNC(E73*D73, 0) -> 0 | G73: =TRUNC('일위대가목록(총체)'!F26,0) -> 0 | H73: =TRUNC(G73*D73, 0) -> 0 | I73: =TRUNC('일위대가목록(총체)'!G26,0) -> 0 | J73: =TRUNC(I73*D73, 0) -> 0 | K73: =TRUNC(E73+G73+I73, 0) -> 0 | L73: =TRUNC(F73+H73+J73, 0) -> 0 | N73: 528C02E65E7E892056AF3039C38A37 | Q73: 0104 | R73: T | S73: F | T73: F | AU73: 0104528C02E65E7E892056AF3039C38A37 | AV73: 35
A74: 합판 2겹 깔기 | B74: 바닥, 12㎜ 내수합판 2겹 | C74: M2 | D74: 115 | E74: =TRUNC('일위대가목록(총체)'!E27,0) -> 0 | F74: =TRUNC(E74*D74, 0) -> 0 | G74: =TRUNC('일위대가목록(총체)'!F27,0) -> 0 | H74: =TRUNC(G74*D74, 0) -> 0 | I74: =TRUNC('일위대가목록(총체)'!G27,0) -> 0 | J74: =TRUNC(I74*D74, 0) -> 0 | K74: =TRUNC(E74+G74+I74, 0) -> 0 | L74: =TRUNC(F74+H74+J74, 0) -> 0 | N74: 528C02E6D3D839CDDF2BA4376372FDC4 | Q74: 0104 | R74: T | S74: F | T74: F | AU74: 0104528C02E6D3D839CDDF2BA4376372FDC4 | AV74: 32
A75: 보통합판 | B75: 보통합판, 1급, 12*1220*2440mm | C75: M2 | D75: 285 | E75: =TRUNC('단가대비표(총체)'!O8,0) -> 0 | F75: =TRUNC(E75*D75, 0) -> 0 | G75: =TRUNC('단가대비표(총체)'!P8,0) -> 0 | H75: =TRUNC(G75*D75, 0) -> 0 | I75: =TRUNC('단가대비표(총체)'!V8,0) -> 0 | J75: =TRUNC(I75*D75, 0) -> 0 | K75: =TRUNC(E75+G75+I75, 0) -> 0 | L75: =TRUNC(F75+H75+J75, 0) -> 0 | N75: 558E22F6D24E09A5E3A74F32A391CBF022DCF4 | Q75: 0104 | R75: F | S75: F | T75: T | AU75: 0104558E22F6D24E09A5E3A74F32A391CBF022DCF4 | AV75: 218
A76: 합판 2겹 깔기 | B76: 바닥, 15㎜ 내수합판 2겹 | C76: M2 | D76: 23 | E76: =TRUNC('일위대가목록(총체)'!E28,0) -> 0 | F76: =TRUNC(E76*D76, 0) -> 0 | G76: =TRUNC('일위대가목록(총체)'!F28,0) -> 0 | H76: =TRUNC(G76*D76, 0) -> 0 | I76: =TRUNC('일위대가목록(총체)'!G28,0) -> 0 | J76: =TRUNC(I76*D76, 0) -> 0 | K76: =TRUNC(E76+G76+I76, 0) -> 0 | L76: =TRUNC(F76+H76+J76, 0) -> 0 | N76: 528C02E6D3D839CDDF2BA4376372FDC7 | Q76: 0104 | R76: T | S76: F | T76: F | AU76: 0104528C02E6D3D839CDDF2BA4376372FDC7 | AV76: 33
...

Sheet 일위대가목록(총체)
A1: 일 위 대 가 목 록
A2: [ 부산역 4층(부고열소) 내부개수 기타공사(총체) ]
A3: 코 드 | B3: 품 명 | C3: 규 격 | D3: 단위 | E3: 재 료 비 | F3: 노 무 비 | G3: 경 비 | H3: 합 계 | I3: 번 호 | J3: 비 고 | K3: 노임계수 | L3: 할증 | M3: 품셈개요 | N3: 장비일위
A4: 528CE206FA04C98EB34FCA3743B093 | B4: 콘테이너형 가설사무소 설치 및 해체 | C4: 3.0*6.0m, 3개월 | D4: 개소 | E4: ='일위대가(총체)'!F8 -> 0 | F4: ='일위대가(총체)'!H8 -> 0 | G4: ='일위대가(총체)'!J8 -> 0 | H4: =E4+F4+G4 -> 0 | I4: 호표 1
A5: 528CE206FA04F95DAB2BC23B235ECF | B5: 콘테이너형 가설창고 설치 및 해체 | C5: 3.0*6.0m, 3개월 | D5: 개소 | E5: ='일위대가(총체)'!F14 -> 0 | F5: ='일위대가(총체)'!H14 -> 0 | G5: ='일위대가(총체)'!J14 -> 0 | H5: =E5+F5+G5 -> 0 | I5: 호표 2
A6: 528CE20691B3B972B985053583A21F | B6: 건축물 현장정리 | C6: 목조, 철골조, 조적조 | D6: M2 | E6: ='일위대가(총체)'!F18 -> 0 | F6: ='일위대가(총체)'!H18 -> 0 | G6: ='일위대가(총체)'!J18 -> 0 | H6: =E6+F6+G6 -> 0 | I6: 호표 3
A7: 528CE206CEDAC9860073CE3B53545E | B7: 강관 조립말비계(이동식)설치 및 해체 | C7: 높이 4m, 3개월 | D7: 대 | E7: ='일위대가(총체)'!F32 -> 0 | F7: ='일위대가(총체)'!H32 -> 0 | G7: ='일위대가(총체)'!J32 -> 0 | H7: =E7+F7+G7 -> 0 | I7: 호표 4
A8: 528CE206CEDAC98602247D3B532581 | B8: 시스템비계 설치 및 해체 | C8: 10m 이하 | D8: M2 | E8: ='일위대가(총체)'!F37 -> 0 | F8: ='일위대가(총체)'!H37 -> 0 | G8: ='일위대가(총체)'!J37 -> 0 | H8: =E8+F8+G8 -> 0 | I8: 호표 5
A9: 528CE206CEF5C913FD184B3B537AB61C | B9: RPP가설울타리판 설치 | C9: 설치높이 6m 이하 | D9: M | E9: ='일위대가(총체)'!F45 -> 0 | F9: ='일위대가(총체)'!H45 -> 0 | G9: ='일위대가(총체)'!J45 -> 0 | H9: =E9+F9+G9 -> 0 | I9: 호표 6
A10: 528CE206CEF5C913FD184B3B537B5CE1 | B10: RPP가설울타리판 해체 | C10: 설치높이 6m 이하 | D10: M | E10: ='일위대가(총체)'!F52 -> 0 | F10: ='일위대가(총체)'!H52 -> 0 | G10: ='일위대가(총체)'!J52 -> 0 | H10: =E10+F10+G10 -> 0 | I10: 호표 7
A11: 528C9286A920C9AA1212993083EF9B | B11: 1.0B 벽돌쌓기 | C11: 3.6m 초과 | D11: M2 | E11: ='일위대가(총체)'!F59 -> 0 | F11: ='일위대가(총체)'!H59 -> 0 | G11: ='일위대가(총체)'!J59 -> 0 | H11: =E11+F11+G11 -> 0 | I11: 호표 8
A12: 528C9286A90419EA3F99A93D539B80 | B12: 벽돌운반 | C12: 인력, 4층 | D12: 천매 | E12: ='일위대가(총체)'!F63 -> 0 | F12: ='일위대가(총체)'!H63 -> 0 | G12: ='일위대가(총체)'!J63 -> 0 | H12: =E12+F12+G12 -> 0 | I12: 호표 9
A13: 528C82A6506BD9409745C83ED332CF | B13: 모르타르 바름 | C13: 내벽, 18mm, 3.6m 초과 | D13: M2 | E13: ='일위대가(총체)'!F68 -> 0 | F13: ='일위대가(총체)'!H68 -> 0 | G13: ='일위대가(총체)'!J68 -> 0 | H13: =E13+F13+G13 -> 0 | I13: 호표 10
A14: 528C82A6506BF97316C7B53683AF23E0 | B14: 구배모르타르 바름 | C14: 바닥, 24mm | D14: M2 | E14: ='일위대가(총체)'!F73 -> 0 | F14: ='일위대가(총체)'!H73 -> 0 | G14: ='일위대가(총체)'!J73 -> 0 | H14: =E14+F14+G14 -> 0 | I14: 호표 11
A15: 528C82A6506BF97316C7B53693B2BA | B15: 모르타르 바름 | C15: 바닥, 30mm | D15: M2 | E15: ='일위대가(총체)'!F78 -> 0 | F15: ='일위대가(총체)'!H78 -> 0 | G15: ='일위대가(총체)'!J78 -> 0 | H15: =E15+F15+G15 -> 0 | I15: 호표 12
A16: 528C82A6506BF908FCCB2A3A031E5119 | B16: 자동 수평 모르타르 바름 | C16: 바닥 10T | D16: M2 | E16: ='일위대가(총체)'!F85 -> 0 | F16: ='일위대가(총체)'!H85 -> 0 | G16: ='일위대가(총체)'!J85 -> 0 | H16: =E16+F16+G16 -> 0 | I16: 호표 13
A17: 528C2236DDB5A9868959173153EBC0 | B17: 타일 떠붙이기(바탕 24mm) | C17: 벽, 0.11∼0.20 이하, 백색줄눈 | D17: M2 | E17: ='일위대가(총체)'!F92 -> 0 | F17: ='일위대가(총체)'!H92 -> 0 | G17: ='일위대가(총체)'!J92 -> 0 | H17: =E17+F17+G17 -> 0 | I17: 호표 14
A18: 528C2236DD9AF9FF62219F3BB320A3 | B18: 타일 압착 붙이기(바탕 12mm+압 5mm) | C18: 바닥, 300*300(타일C, 백색줄눈) | D18: M2 | E18: ='일위대가(총체)'!F98 -> 0 | F18: ='일위대가(총체)'!H98 -> 0 | G18: ='일위대가(총체)'!J98 -> 0 | H18: =E18+F18+G18 -> 0 | I18: 호표 15
A19: 528C2236EE62B987D089DD3563E2B14D | B19: 화강석 두겁돌(습식, 물갈기) | C19: 창대, 마천석 120*30mm, 모르타르 30mm | D19: M | E19: ='일위대가(총체)'!F104 -> 0 | F19: ='일위대가(총체)'!H104 -> 0 | G19: ='일위대가(총체)'!J104 -> 0 | H19: =E19+F19+G19 -> 0 | I19: 호표 16
A20: 528C72B6D26AD9C653490E35E304BB | B20: 수용성 고무화 아스팔트방수 | C20: 바닥, 비노출 | D20: M2 | E20: ='일위대가(총체)'!F115 -> 0 | F20: ='일위대가(총체)'!H115 -> 0 | G20: ='일위대가(총체)'!J115 -> 0 | H20: =E20+F20+G20 -> 0 | I20: 호표 17
A21: 528C72B6D26AD9C653490E35E304BA | B21: 수용성 고무화 아스팔트방수 | C21: 벽, 비노출 | D21: M2 | E21: ='일위대가(총체)'!F126 -> 0 | F21: ='일위대가(총체)'!H126 -> 0 | G21: ='일위대가(총체)'!J126 -> 0 | H21: =E21+F21+G21 -> 0 | I21: 호표 18
A22: 528C72B679E069B4976E273913F293 | B22: 시멘트 액체방수 바름 | C22: 바닥 | D22: M2 | E22: ='일위대가(총체)'!F135 -> 0 | F22: ='일위대가(총체)'!H135 -> 0 | G22: ='일위대가(총체)'!J135 -> 0 | H22: =E22+F22+G22 -> 0 | I22: 호표 19
A23: 528C72B679E069B4976E273913F2935C | B23: 시멘트 액체방수 바름 | C23: 벽 | D23: M2 | E23: ='일위대가(총체)'!F144 -> 0 | F23: ='일위대가(총체)'!H144 -> 0 | G23: ='일위대가(총체)'!J144 -> 0 | H23: =E23+F23+G23 -> 0 | I23: 호표 20
A24: 528C625664E5499988B0D5373338BE | B24: 마루틀 설치 | C24: 45*45, @450 | D24: M2 | E24: ='일위대가(총체)'!F149 -> 0 | F24: ='일위대가(총체)'!H149 -> 0 | G24: ='일위대가(총체)'!J149 -> 0 | H24: =E24+F24+G24 -> 0 | I24: 호표 21
A25: 528C625664E5499988B1F23193C65A | B25: 마루틀 설치 | C25: 90*90, @900 | D25: M2 | E25: ='일위대가(총체)'!F154 -> 0 | F25: ='일위대가(총체)'!H154 -> 0 | G25: ='일위대가(총체)'!J154 -> 0 | H25: =E25+F25+G25 -> 0 | I25: 호표 22
A26: 528C02E65E7E892056AF3039C38A37 | B26: 마루귀틀 설치 | D26: M | E26: ='일위대가(총체)'!F160 -> 0 | F26: ='일위대가(총체)'!H160 -> 0 | G26: ='일위대가(총체)'!J160 -> 0 | H26: =E26+F26+G26 -> 0 | I26: 호표 23
A27: 528C02E6D3D839CDDF2BA4376372FDC4 | B27: 합판 2겹 깔기 | C27: 바닥, 12㎜ 내수합판 2겹 | D27: M2 | E27: ='일위대가(총체)'!F167 -> 0 | F27: ='일위대가(총체)'!H167 -> 0 | G27: ='일위대가(총체)'!J167 -> 0 | H27: =E27+F27+G27 -> 0 | I27: 호표 24
A28: 528C02E6D3D839CDDF2BA4376372FDC7 | B28: 합판 2겹 깔기 | C28: 바닥, 15㎜ 내수합판 2겹 | D28: M2 | E28: ='일위대가(총체)'!F174 -> 0 | F28: ='일위대가(총체)'!H174 -> 0 | G28: ='일위대가(총체)'!J174 -> 0 | H28: =E28+F28+G28 -> 0 | I28: 호표 25
A29: 528C02E6D3D839CDDF2BA4376372FDC1 | B29: 벽, T15 목모흡음보드 붙임 | C29: T15, 국내산 | D29: M2 | E29: ='일위대가(총체)'!F181 -> 0 | F29: ='일위대가(총체)'!H181 -> 0 | G29: ='일위대가(총체)'!J181 -> 0 | H29: =E29+F29+G29 -> 0 | I29: 호표 26
A30: 528C02E6D3D839CDDF2BA4376372FDC0 | B30: 차은시트 붙임 | C30: 2T | D30: M2 | E30: ='일위대가(총체)'!F187 -> 0 | F30: ='일위대가(총체)'!H187 -> 0 | G30: ='일위대가(총체)'!J187 -> 0 | H30: =E30+F30+G30 -> 0 | I30: 호표 27
A31: 528C3226AB96A98EFBAEF431D36B364C | B31: 백페인트글라스 붙이기 | C31: T8, 화이트보드, 제비스코 | D31: M2 | E31: ='일위대가(총체)'!F195 -> 0 | F31: ='일위대가(총체)'!H195 -> 0 | G31: ='일위대가(총체)'!J195 -> 0 | H31: =E31+F31+G31 -> 0 | I31: 호표 28
A32: 528C02E6A64A09867EA349356391B0 | B32: 단열재 깔기 | C32: 압출발포폴리스티렌단열재, 압출, 0.03, 100mm | D32: M2 | E32: ='일위대가(총체)'!F200 -> 0 | F32: ='일위대가(총체)'!H200 -> 0 | G32: ='일위대가(총체)'!J200 -> 0 | H32: =E32+F32+G32 -> 0 | I32: 호표 29
A33: 528C02E6D3BD59526658B239C38B41 | B33: 석고판 설치(나사고정) - 바탕용 | C33: 벽, 2겹 붙임 | D33: M2 | E33: ='일위대가(총체)'!F206 -> 0 | F33: ='일위대가(총체)'!H206 -> 0 | G33: ='일위대가(총체)'!J206 -> 0 | H33: =E33+F33+G33 -> 0 | I33: 호표 30
A34: 528C02E6D3BD59515F678133438DF2 | B34: 석고판 설치(나사고정) - 바탕용 | C34: 천장, 1겹 붙임 | D34: M2 | E34: ='일위대가(총체)'!F212 -> 0 | F34: ='일위대가(총체)'!H212 -> 0 | G34: ='일위대가(총체)'!J212 -> 0 | H34: =E34+F34+G34 -> 0 | I34: 호표 31
A35: 528C02E6D3BD59515F678133438E98 | B35: 석고판 설치(나사고정) - 바탕용 | C35: 천장, 2겹 붙임 | D35: M2 | E35: ='일위대가(총체)'!F218 -> 0 | F35: ='일위대가(총체)'!H218 -> 0 | G35: ='일위대가(총체)'!J218 -> 0 | H35: =E35+F35+G35 -> 0 | I35: 호표 32
A36: 528C527674AE490248499A37A3BF37AC | B36: 드라이월 벽 설치(일반) | C36: 일반 9.5mm 양면 2겹 C-골조 125현 이하 | D36: ㎡ | E36: ='일위대가(총체)'!F227 -> 0 | F36: ='일위대가(총체)'!H227 -> 0 | G36: ='일위대가(총체)'!J227 -> 0 | H36: =E36+F36+G36 -> 0 | I36: 호표 33
A37: 528C527674AE490248499A37A3BF37AF | B37: 드라이월 벽 설치(방화) | C37: 방화 12.5mm 양면 2겹 C-골조 125현 이하 | D37: ㎡ | E37: ='일위대가(총체)'!F236 -> 0 | F37: ='일위대가(총체)'!H236 -> 0 | G37: ='일위대가(총체)'!J236 -> 0 | H37: =E37+F37+G37 -> 0 | I37: 호표 34
A38: 528C02E6A677496478D8DC3033CD045C | B38: 단열재 격자넣기 - 벽 | C38: 그라스울 24K, 50T*450*1000 | D38: M2 | E38: ='일위대가(총체)'!F241 -> 0 | F38: ='일위대가(총체)'!H241 -> 0 | G38: ='일위대가(총체)'!J241 -> 0 | H38: =E38+F38+G38 -> 0 | I38: 호표 35
A39: 528C02E6FE7409FF40712B3103D588 | B39: 비닐타일 깔기 | C39: 비닐타일, 3*450*450mm, 데코타일 | D39: M2 | E39: ='일위대가(총체)'!F245 -> 0 | F39: ='일위대가(총체)'!H245 -> 0 | G39: ='일위대가(총체)'!J245 -> 0 | H39: =E39+F39+G39 -> 0 | I39: 호표 36
A40: 528C02E6FE7409FEBC732B3DF33866 | B40: 비닐시트 깔기 - 전면접합 | C40: 비닐시트, 2.0mm, 모노륨 | D40: M2 | E40: ='일위대가(총체)'!F249 -> 0 | F40: ='일위대가(총체)'!H249 -> 0 | G40: ='일위대가(총체)'!J249 -> 0 | H40: =E40+F40+G40 -> 0 | I40: 호표 37
...

Sheet 일위대가(총체)
A1: [ 부산역 4층(부고열소) 내부개수 기타공사(총체) ]
A2: 품 명 | B2: 규 격 | C2: 단위 | D2: 수량 | E2: 재 료 비 | G2: 노 무 비 | I2: 경 비 | K2: 합 계 | M2: 비 고 | N2: 일위대가 | O2: 품목코드 | P2: 일위 | Q2: 단산 | R2: 자재 | S2: 손료적용 | T2: 손료저장 | U2: 적용율 | V2: JUK1 | W2: JUK2 | X2: JUK3 | Y2: JUK4 | Z2: JUK5 | AA2: JUK6 | AB2: JUK7 | AC2: JUK8 | AD2: JUK9 | AE2: JUK10 | AF2: JUK11 | AG2: JUK12 | AH2: JUK13 | AI2: JUK14 | AJ2: JUK15 | AK2: JUK16 | AL2: JUK17 | AM2: JUK18 | AN2: JUK19 | AO2: JUK20 | AP2: 할증적용 | AQ2: 할증저장 | AR2: 할증율 | AS2: HAL1 | AT2: HAL2 | AU2: HAL3 | AV2: 자재구분 | AW2: 일위대가+자재 | AX2: 장비일위 | AY2: 설정
E3: 단 가 | F3: 금 액 | G3: 단 가 | H3: 금 액 | I3: 단 가 | J3: 금 액 | K3: 단 가 | L3: 금 액
A4: 콘테이너형 가설사무소 설치 및 해체 3.0*6.0m, 3개월 개소 ( 호표 1 ) | N4: 528CE206FA04C98EB34FCA3743B093
A5: 컨테이너하우스 | B5: 컨테이너하우스, 사무실용, 3.0*6.0*2.6m | C5: 개 | D5: 0.18 | E5: ='단가대비표(총체)'!O107 -> 0 | F5: =TRUNC(E5*D5,1) -> 0 | G5: ='단가대비표(총체)'!P107 -> 0 | H5: =TRUNC(G5*D5,1) -> 0 | I5: ='단가대비표(총체)'!V107 -> 0 | J5: =TRUNC(I5*D5,1) -> 0 | K5: =TRUNC(E5+G5+I5,1) -> 0 | L5: =TRUNC(F5+H5+J5,1) -> 0 | M5: 금액제외 | O5: 55A91276C7E1199B5DDF2A35C342C267C6D383 | P5: F | Q5: F | R5: T | V5: 1 | AW5: 528CE206FA04C98EB34FCA3743B09355A91276C7E1199B5DDF2A35C342C267C6D383 | AY5: -
A6: 콘테이너형 가설건축물 설치 및 해체 | B6: 3.0*6.0m | C6: 개소 | D6: 1 | E6: ='일위대가목록(총체)'!E134 -> 0 | F6: =TRUNC(E6*D6,1) -> 0 | G6: ='일위대가목록(총체)'!F134 -> 0 | H6: =TRUNC(G6*D6,1) -> 0 | I6: ='일위대가목록(총체)'!G134 -> 0 | J6: =TRUNC(I6*D6,1) -> 0 | K6: =TRUNC(E6+G6+I6,1) -> 0 | L6: =TRUNC(F6+H6+J6,1) -> 0 | M6: 금액제외 | O6: 528CE206FA04C98EBB858B3943BAB8 | P6: T | Q6: F | R6: F | V6: 1 | AW6: 528CE206FA04C98EB34FCA3743B093528CE206FA04C98EBB858B3943BAB8 | AY6: -
A7: 경비로 적용 | B7: 합계의 100% | C7: 식 | D7: 1 | E7: 0 | F7: =TRUNC(E7*D7,1) -> 0 | G7: 0 | H7: =TRUNC(G7*D7,1) -> 0 | I7: =TRUNC(SUMIF(V5:V7, RIGHTB(O7, 1), L5:L7)*U7, 2) -> 0 | J7: =TRUNC(I7*D7,1) -> 0 | K7: =TRUNC(E7+G7+I7,1) -> 0 | L7: =TRUNC(F7+H7+J7,1) -> 0 | N7: 528CE206FA04C98EB34FCA3743B093 | O7: 539B22A6953859AA28AAA535B340001 | P7: F | Q7: F | R7: F | S7: 3 | T7: 2 | U7: 1 | AW7: 528CE206FA04C98EB34FCA3743B093539B22A6953859AA28AAA535B340001
A8: [ 합 계 ] | F8: =TRUNC(SUMIF(N5:N7, N4, F5:F7),0) -> 0 | H8: =TRUNC(SUMIF(N5:N7, N4, H5:H7),0) -> 0 | J8: =TRUNC(SUMIF(N5:N7, N4, J5:J7),0) -> 0 | L8: =F8+H8+J8 -> 0 | N8: TOTAL | O8: TOTAL
A10: 콘테이너형 가설창고 설치 및 해체 3.0*6.0m, 3개월 개소 ( 호표 2 ) | N10: 528CE206FA04F95DAB2BC23B235ECF
A11: 컨테이너하우스 | B11: 컨테이너하우스, 창고용, 3.0*6.0*2.6m | C11: 개 | D11: 0.18 | E11: ='단가대비표(총체)'!O108 -> 0 | F11: =TRUNC(E11*D11,1) -> 0 | G11: ='단가대비표(총체)'!P108 -> 0 | H11: =TRUNC(G11*D11,1) -> 0 | I11: ='단가대비표(총체)'!V108 -> 0 | J11: =TRUNC(I11*D11,1) -> 0 | K11: =TRUNC(E11+G11+I11,1) -> 0 | L11: =TRUNC(F11+H11+J11,1) -> 0 | M11: 금액제외 | O11: 55A91276C7E1199B5DDF2A35C342C267C6D5BA | P11: F | Q11: F | R11: T | V11: 1 | AW11: 528CE206FA04F95DAB2BC23B235ECF55A91276C7E1199B5DDF2A35C342C267C6D5BA | AY11: -
A12: 콘테이너형 가설건축물 설치 및 해체 | B12: 3.0*6.0m | C12: 개소 | D12: 1 | E12: ='일위대가목록(총체)'!E134 -> 0 | F12: =TRUNC(E12*D12,1) -> 0 | G12: ='일위대가목록(총체)'!F134 -> 0 | H12: =TRUNC(G12*D12,1) -> 0 | I12: ='일위대가목록(총체)'!G134 -> 0 | J12: =TRUNC(I12*D12,1) -> 0 | K12: =TRUNC(E12+G12+I12,1) -> 0 | L12: =TRUNC(F12+H12+J12,1) -> 0 | M12: 금액제외 | O12: 528CE206FA04C98EBB858B3943BAB8 | P12: T | Q12: F | R12: F | V12: 1 | AW12: 528CE206FA04F95DAB2BC23B235ECF528CE206FA04C98EBB858B3943BAB8 | AY12: -
A13: 경비로 적용 | B13: 합계의 100% | C13: 식 | D13: 1 | E13: 0 | F13: =TRUNC(E13*D13,1) -> 0 | G13: 0 | H13: =TRUNC(G13*D13,1) -> 0 | I13: =TRUNC(SUMIF(V11:V13, RIGHTB(O13, 1), L11:L13)*U13, 2) -> 0 | J13: =TRUNC(I13*D13,1) -> 0 | K13: =TRUNC(E13+G13+I13,1) -> 0 | L13: =TRUNC(F13+H13+J13,1) -> 0 | N13: 528CE206FA04F95DAB2BC23B235ECF | O13: 539B22A6953859AA28AAA535B340001 | P13: F | Q13: F | R13: F | S13: 3 | T13: 2 | U13: 1 | AW13: 528CE206FA04F95DAB2BC23B235ECF539B22A6953859AA28AAA535B340001
A14: [ 합 계 ] | F14: =TRUNC(SUMIF(N11:N13, N10, F11:F13),0) -> 0 | H14: =TRUNC(SUMIF(N11:N13, N10, H11:H13),0) -> 0 | J14: =TRUNC(SUMIF(N11:N13, N10, J11:J13),0) -> 0 | L14: =F14+H14+J14 -> 0 | N14: TOTAL | O14: TOTAL
A16: 건축물 현장정리 목조, 철골조, 조적조 M2 ( 호표 3 ) | N16: 528CE20691B3B972B985053583A21F
A17: 보통인부 | B17: 일반공사 직종 | C17: 인 | D17: 0.05 | E17: ='단가대비표(총체)'!O180 -> 0 | F17: =TRUNC(E17*D17,1) -> 0 | G17: ='단가대비표(총체)'!P180 -> 0 | H17: =TRUNC(G17*D17,1) -> 0 | I17: ='단가대비표(총체)'!V180 -> 0 | J17: =TRUNC(I17*D17,1) -> 0 | K17: =TRUNC(E17+G17+I17,1) -> 0 | L17: =TRUNC(F17+H17+J17,1) -> 0 | N17: 528CE20691B3B972B985053583A21F | O17: 525EB2169A3C69E10E693C3EB327F425525855 | P17: F | Q17: F | R17: T | AW17: 528CE20691B3B972B985053583A21F525EB2169A3C69E10E693C3EB327F425525855
A18: [ 합 계 ] | F18: =TRUNC(SUMIF(N17:N17, N16, F17:F17),0) -> 0 | H18: =TRUNC(SUMIF(N17:N17, N16, H17:H17),0) -> 0 | J18: =TRUNC(SUMIF(N17:N17, N16, J17:J17),0) -> 0 | L18: =F18+H18+J18 -> 0 | N18: TOTAL | O18: TOTAL
A20: 강관 조립말비계(이동식)설치 및 해체 높이 4m, 3개월 대 ( 호표 4 ) | N20: 528CE206CEDAC9860073CE3B53545E
A21: 비계안정장치 | B21: 비계안정장치, 비계기본틀, 기둥, 1.2*1.7m | C21: 개 | D21: 0.24 | E21: ='단가대비표(총체)'!O98 -> 0 | F21: =TRUNC(E21*D21,1) -> 0 | G21: ='단가대비표(총체)'!P98 -> 0 | H21: =TRUNC(G21*D21,1) -> 0 | I21: ='단가대비표(총체)'!V98 -> 0 | J21: =TRUNC(I21*D21,1) -> 0 | K21: =TRUNC(E21+G21+I21,1) -> 0 | L21: =TRUNC(F21+H21+J21,1) -> 0 | N21: 528CE206CEDAC9860073CE3B53545E | O21: 55A91276F387E9FF4D387D3A933811961EBFE0 | P21: F | Q21: F | R21: T | AW21: 528CE206CEDAC9860073CE3B53545E55A91276F387E9FF4D387D3A933811961EBFE0
A22: 비계안정장치 | B22: 비계안정장치, 가새, 1.2*1.9m | C22: 개 | D22: 0.24 | E22: ='단가대비표(총체)'!O99 -> 0 | F22: =TRUNC(E22*D22,1) -> 0 | G22: ='단가대비표(총체)'!P99 -> 0 | H22: =TRUNC(G22*D22,1) -> 0 | I22: ='단가대비표(총체)'!V99 -> 0 | J22: =TRUNC(I22*D22,1) -> 0 | K22: =TRUNC(E22+G22+I22,1) -> 0 | L22: =TRUNC(F22+H22+J22,1) -> 0 | N22: 528CE206CEDAC9860073CE3B53545E | O22: 55A91276F387E9FF4D387D3A933811961EBFEE | P22: F | Q22: F | R22: T | AW22: 528CE206CEDAC9860073CE3B53545E55A91276F387E9FF4D387D3A933811961EBFEE
A23: 비계안정장치 | B23: 비계안정장치, 수평띠장, 1829mm | C23: 개 | D23: 0.48 | E23: ='단가대비표(총체)'!O100 -> 0 | F23: =TRUNC(E23*D23,1) -> 0 | G23: ='단가대비표(총체)'!P100 -> 0 | H23: =TRUNC(G23*D23,1) -> 0 | I23: ='단가대비표(총체)'!V100 -> 0 | J23: =TRUNC(I23*D23,1) -> 0 | K23: =TRUNC(E23+G23+I23,1) -> 0 | L23: =TRUNC(F23+H23+J23,1) -> 0 | N23: 528CE206CEDAC9860073CE3B53545E | O23: 55A91276F387E9FF4D387D3A933811961EB063 | P23: F | Q23: F | R23: T | AW23: 528CE206CEDAC9860073CE3B53545E55A91276F387E9FF4D387D3A933811961EB063
A24: 비계안정장치 | B24: 비계안정장치, 손잡이기둥 | C24: 개 | D24: 0.24 | E24: ='단가대비표(총체)'!O103 -> 0 | F24: =TRUNC(E24*D24,1) -> 0 | G24: ='단가대비표(총체)'!P103 -> 0 | H24: =TRUNC(G24*D24,1) -> 0 | I24: ='단가대비표(총체)'!V103 -> 0 | J24: =TRUNC(I24*D24,1) -> 0 | K24: =TRUNC(E24+G24+I24,1) -> 0 | L24: =TRUNC(F24+H24+J24,1) -> 0 | N24: 528CE206CEDAC9860073CE3B53545E | O24: 55A91276F387E9FF4D387D3A933811961EB064 | P24: F | Q24: F | R24: T | AW24: 528CE206CEDAC9860073CE3B53545E55A91276F387E9FF4D387D3A933811961EB064
A25: 비계안정장치 | B25: 비계안정장치, 손잡이, 1229mm | C25: 개 | D25: 0.12 | E25: ='단가대비표(총체)'!O101 -> 0 | F25: =TRUNC(E25*D25,1) -> 0 | G25: ='단가대비표(총체)'!P101 -> 0 | H25: =TRUNC(G25*D25,1) -> 0 | I25: ='단가대비표(총체)'!V101 -> 0 | J25: =TRUNC(I25*D25,1) -> 0 | K25: =TRUNC(E25+G25+I25,1) -> 0 | L25: =TRUNC(F25+H25+J25,1) -> 0 | N25: 528CE206CEDAC9860073CE3B53545E | O25: 55A91276F387E9FF4D387D3A933811961EB062 | P25: F | Q25: F | R25: T | AW25: 528CE206CEDAC9860073CE3B53545E55A91276F387E9FF4D387D3A933811961EB062
A26: 비계안정장치 | B26: 비계안정장치, 손잡이, 1829mm | C26: 개 | D26: 0.24 | E26: ='단가대비표(총체)'!O102 -> 0 | F26: =TRUNC(E26*D26,1) -> 0 | G26: ='단가대비표(총체)'!P102 -> 0 | H26: =TRUNC(G26*D26,1) -> 0 | I26: ='단가대비표(총체)'!V102 -> 0 | J26: =TRUNC(I26*D26,1) -> 0 | K26: =TRUNC(E26+G26+I26,1) -> 0 | L26: =TRUNC(F26+H26+J26,1) -> 0 | N26: 528CE206CEDAC9860073CE3B53545E | O26: 55A91276F387E9FF4D387D3A933811961EB065 | P26: F | Q26: F | R26: T | AW26: 528CE206CEDAC9860073CE3B53545E55A91276F387E9FF4D387D3A933811961EB065
A27: 비계안정장치 | B27: 비계안정장치, 이음철물, 연결핀 | C27: 개 | D27: 0.48 | E27: ='단가대비표(총체)'!O97 -> 0 | F27: =TRUNC(E27*D27,1) -> 0 | G27: ='단가대비표(총체)'!P97 -> 0 | H27: =TRUNC(G27*D27,1) -> 0 | I27: ='단가대비표(총체)'!V97 -> 0 | J27: =TRUNC(I27*D27,1) -> 0 | K27: =TRUNC(E27+G27+I27,1) -> 0 | L27: =TRUNC(F27+H27+J27,1) -> 0 | N27: 528CE206CEDAC9860073CE3B53545E | O27: 55A91276F387E9FF4D387D3A933811961EBD3E | P27: F | Q27: F | R27: T | AW27: 528CE206CEDAC9860073CE3B53545E55A91276F387E9FF4D387D3A933811961EBD3E
A28: 비계안정장치 | B28: 비계안정장치, 바퀴 | C28: 개 | D28: 0.36 | E28: ='단가대비표(총체)'!O104 -> 0 | F28: =TRUNC(E28*D28,1) -> 0 | G28: ='단가대비표(총체)'!P104 -> 0 | H28: =TRUNC(G28*D28,1) -> 0 | I28: ='단가대비표(총체)'!V104 -> 0 | J28: =TRUNC(I28*D28,1) -> 0 | K28: =TRUNC(E28+G28+I28,1) -> 0 | L28: =TRUNC(F28+H28+J28,1) -> 0 | N28: 528CE206CEDAC9860073CE3B53545E | O28: 55A91276F387E9FF4D387D3A933811961EB067 | P28: F | Q28: F | R28: T | AW28: 528CE206CEDAC9860073CE3B53545E55A91276F387E9FF4D387D3A933811961EB067
A29: 비계안정장치 | B29: 비계안정장치, 쟈키 | C29: 개 | D29: 0.36 | E29: ='단가대비표(총체)'!O105 -> 0 | F29: =TRUNC(E29*D29,1) -> 0 | G29: ='단가대비표(총체)'!P105 -> 0 | H29: =TRUNC(G29*D29,1) -> 0 | I29: ='단가대비표(총체)'!V105 -> 0 | J29: =TRUNC(I29*D29,1) -> 0 | K29: =TRUNC(E29+G29+I29,1) -> 0 | L29: =TRUNC(F29+H29+J29,1) -> 0 | N29: 528CE206CEDAC9860073CE3B53545E | O29: 55A91276F387E9FF4D387D3A933811961EB066 | P29: F | Q29: F | R29: T | AW29: 528CE206CEDAC9860073CE3B53545E55A91276F387E9FF4D387D3A933811961EB066
A30: 비계안정장치 | B30: 비계안정장치, 발판, 40*200*2000 | C30: 장 | D30: 0.63 | E30: ='단가대비표(총체)'!O106 -> 0 | F30: =TRUNC(E30*D30,1) -> 0 | G30: ='단가대비표(총체)'!P106 -> 0 | H30: =TRUNC(G30*D30,1) -> 0 | I30: ='단가대비표(총체)'!V106 -> 0 | J30: =TRUNC(I30*D30,1) -> 0 | K30: =TRUNC(E30+G30+I30,1) -> 0 | L30: =TRUNC(F30+H30+J30,1) -> 0 | N30: 528CE206CEDAC9860073CE3B53545E | O30: 55A91276F387E9FF4D387D3AB3E5A911184850 | P30: F | Q30: F | R30: T | AW30: 528CE206CEDAC9860073CE3B53545E55A91276F387E9FF4D387D3AB3E5A911184850
A31: 강관 조립말비계(이동식)설치 및 해체 | B31: 높이 4m, 노무비 | C31: 대 | D31: 1 | E31: ='일위대가목록(총체)'!E136 -> 0 | F31: =TRUNC(E31*D31,1) -> 0 | G31: ='일위대가목록(총체)'!F136 -> 0 | H31: =TRUNC(G31*D31,1) -> 0 | I31: ='일위대가목록(총체)'!G136 -> 0 | J31: =TRUNC(I31*D31,1) -> 0 | K31: =TRUNC(E31+G31+I31,1) -> 0 | L31: =TRUNC(F31+H31+J31,1) -> 0 | N31: 528CE206CEDAC9860073CE3B53545E | O31: 528CE206CEDAC9860073CC388362E3 | P31: T | Q31: F | R31: F | AW31: 528CE206CEDAC9860073CE3B53545E528CE206CEDAC9860073CC388362E3
A32: [ 합 계 ] | F32: =TRUNC(SUMIF(N21:N31, N20, F21:F31),0) -> 0 | H32: =TRUNC(SUMIF(N21:N31, N20, H21:H31),0) -> 0 | J32: =TRUNC(SUMIF(N21:N31, N20, J21:J31),0) -> 0 | L32: =F32+H32+J32 -> 0 | N32: TOTAL | O32: TOTAL
A34: 시스템비계 설치 및 해체 10m 이하 M2 ( 호표 5 ) | N34: 528CE206CEDAC98602247D3B532581
A35: 비계공 | B35: 일반공사 직종 | C35: 인 | D35: 0.04 | E35: ='단가대비표(총체)'!O182 -> 0 | F35: =TRUNC(E35*D35,1) -> 0 | G35: ='단가대비표(총체)'!P182 -> 0 | H35: =TRUNC(G35*D35,1) -> 0 | I35: ='단가대비표(총체)'!V182 -> 0 | J35: =TRUNC(I35*D35,1) -> 0 | K35: =TRUNC(E35+G35+I35,1) -> 0 | L35: =TRUNC(F35+H35+J35,1) -> 0 | N35: 528CE206CEDAC98602247D3B532581 | O35: 525EB2169A3C69E10E693C3EB327F425525851 | P35: F | Q35: F | R35: T | AW35: 528CE206CEDAC98602247D3B532581525EB2169A3C69E10E693C3EB327F425525851
A36: 보통인부 | B36: 일반공사 직종 | C36: 인 | D36: 0.01 | E36: ='단가대비표(총체)'!O180 -> 0 | F36: =TRUNC(E36*D36,1) -> 0 | G36: ='단가대비표(총체)'!P180 -> 0 | H36: =TRUNC(G36*D36,1) -> 0 | I36: ='단가대비표(총체)'!V180 -> 0 | J36: =TRUNC(I36*D36,1) -> 0 | K36: =TRUNC(E36+G36+I36,1) -> 0 | L36: =TRUNC(F36+H36+J36,1) -> 0 | N36: 528CE206CEDAC98602247D3B532581 | O36: 525EB2169A3C69E10E693C3EB327F425525855 | P36: F | Q36: F | R36: T | AW36: 528CE206CEDAC98602247D3B532581525EB2169A3C69E10E693C3EB327F425525855
A37: [ 합 계 ] | F37: =TRUNC(SUMIF(N35:N36, N34, F35:F36),0) -> 0 | H37: =TRUNC(SUMIF(N35:N36, N34, H35:H36),0) -> 0 | J37: =TRUNC(SUMIF(N35:N36, N34, J35:J36),0) -> 0 | L37: =F37+H37+J37 -> 0 | N37: TOTAL | O37: TOTAL
A39: RPP가설울타리판 설치 설치높이 6m 이하 M ( 호표 6 ) | N39: 528CE206CEF5C913FD184B3B537AB61C
A40: RPP 가설흡음형 방음판 | B40: H-667*40T | C40: ㎡ | D40: 4 | E40: ='단가대비표(총체)'!O35 -> 0 | F40: =TRUNC(E40*D40,1) -> 0 | G40: ='단가대비표(총체)'!P35 -> 0 | H40: =TRUNC(G40*D40,1) -> 0 | I40: ='단가대비표(총체)'!V35 -> 0 | J40: =TRUNC(I40*D40,1) -> 0 | K40: =TRUNC(E40+G40+I40,1) -> 0 | L40: =TRUNC(F40+H40+J40,1) -> 0 | N40: 528CE206CEF5C913FD184B3B537AB61C | O40: 55A91276F33FC9B81C1B63395392CE628CD7387C | P40: F | Q40: F | R40: T | V40: 1 | W40: 2 | AW40: 528CE206CEF5C913FD184B3B537AB61C55A91276F33FC9B81C1B63395392CE628CD7387C
A41: 비계공 | B41: 일반공사 직종 | C41: 인 | D41: 0.03 | E41: ='단가대비표(총체)'!O182 -> 0 | F41: =TRUNC(E41*D41,1) -> 0 | G41: ='단가대비표(총체)'!P182 -> 0 | H41: =TRUNC(G41*D41,1) -> 0 | I41: ='단가대비표(총체)'!V182 -> 0 | J41: =TRUNC(I41*D41,1) -> 0 | K41: =TRUNC(E41+G41+I41,1) -> 0 | L41: =TRUNC(F41+H41+J41,1) -> 0 | M41: 금액제외 | O41: 525EB2169A3C69E10E693C3EB327F425525851 | P41: F | Q41: F | R41: T | V41: 1 | W41: 2 | AW41: 528CE206CEF5C913FD184B3B537AB61C525EB2169A3C69E10E693C3EB327F425525851 | AY41: -
A42: 보통인부 | B42: 일반공사 직종 | C42: 인 | D42: 0.011 | E42: ='단가대비표(총체)'!O180 -> 0 | F42: =TRUNC(E42*D42,1) -> 0 | G42: ='단가대비표(총체)'!P180 -> 0 | H42: =TRUNC(G42*D42,1) -> 0 | I42: ='단가대비표(총체)'!V180 -> 0 | J42: =TRUNC(I42*D42,1) -> 0 | K42: =TRUNC(E42+G42+I42,1) -> 0 | L42: =TRUNC(F42+H42+J42,1) -> 0 | M42: 금액제외 | O42: 525EB2169A3C69E10E693C3EB327F425525855 | P42: F | Q42: F | R42: T | V42: 1 | W42: 2 | AW42: 528CE206CEF5C913FD184B3B537AB61C525EB2169A3C69E10E693C3EB327F425525855 | AY42: -
A43: 공구손료 | B43: 인력품의 3% | C43: 식 | D43: 1 | E43: 0 | F43: =TRUNC(E43*D43,1) -> 0 | G43: 0 | H43: =TRUNC(G43*D43,1) -> 0 | I43: =TRUNC(SUMIF(V40:V44, RIGHTB(O43, 1), H40:H44)*U43, 2) -> 0 | J43: =TRUNC(I43*D43,1) -> 0 | K43: =TRUNC(E43+G43+I43,1) -> 0 | L43: =TRUNC(F43+H43+J43,1) -> 0 | M43: 금액제외 | O43: 539B22A6953859AA28AAA535B340001 | P43: F | Q43: F | R43: F | S43: 1 | T43: 2 | U43: 0.03 | W43: 2 | AW43: 528CE206CEF5C913FD184B3B537AB61C539B22A6953859AA28AAA535B340001 | AY43: -
A44: 경비로 적용 | B44: 합계의 100% | C44: 식 | D44: 1 | E44: 0 | F44: =TRUNC(E44*D44,1) -> 0 | G44: 0 | H44: =TRUNC(G44*D44,1) -> 0 | I44: =TRUNC(SUMIF(W40:W44, RIGHTB(O44, 1), L40:L44)*U44, 2) -> 0 | J44: =TRUNC(I44*D44,1) -> 0 | K44: =TRUNC(E44+G44+I44,1) -> 0 | L44: =TRUNC(F44+H44+J44,1) -> 0 | N44: 528CE206CEF5C913FD184B3B537AB61C | O44: 539B22A6953859AA28AAA535B343002 | P44: F | Q44: F | R44: F | S44: 3 | T44: 2 | U44: 1 | AW44: 528CE206CEF5C913FD184B3B537AB61C539B22A6953859AA28AAA535B343002
A45: [ 합 계 ] | F45: =TRUNC(SUMIF(N40:N44, N39, F40:F44),0) -> 0 | H45: =TRUNC(SUMIF(N40:N44, N39, H40:H44),0) -> 0 | J45: =TRUNC(SUMIF(N40:N44, N39, J40:J44),0) -> 0 | L45: =F45+H45+J45 -> 0 | N45: TOTAL | O45: TOTAL
...

Sheet 단가대비표(총체)
A1: 단 가 대 비 표
A2: [ 부산역 4층(부고열소) 내부개수 기타공사(총체) ]
A3: 코 드 | B3: 품 명 | C3: 규격 | D3: 단위 | E3: 재 료 비 | P3: 노 무 비 | Q3: 경 비 | W3: 번 호 | X3: 비 고 | Y3: 품목구분 | Z3: 노임구분 | AA3: 소수점처리 | AB3: 자재구분
E4: 조달청가격 | F4: PAGE | G4: 거래가격 | H4: PAGE | I4: 유통물가 | J4: PAGE | K4: 조사가격1 | L4: PAGE | M4: 조사가격2 | N4: PAGE | O4: 적용단가 | Q4: 조달청가격 | R4: 거래가격 | S4: 유통물가 | T4: 조사가격1 | U4: 조사가격2 | V4: 적용단가
A5: 5598A206DDB8894D5BFEB939A38989B97BC4DD | B5: 크레인(타이어) | C5: 10ton | D5: 대 | W5: 자재 1 | X5: 천원
A6: 5598A206DDB8F9F9F7032031D3A0EA11F75B50 | B6: 소형브레이커(전기식) | C6: 1.5kw | D6: 대 | W6: 자재 2 | X6: 천원
A7: 558E22F6D27B79DF31E62538A38FD09941FD79 | B7: 모래 | C7: 모래, 부산, 도착도 | D7: M3 | W7: 자재 3
A8: 558E22F6D24E09A5E3A74F32A391CBF022DCF4 | B8: 보통합판 | C8: 보통합판, 1급, 12*1220*2440mm | D8: M2 | W8: 자재 4
A9: 558E22F6D24E09A5E3A74F32A391CBF022DCFA | B9: 보통합판 | C9: 보통합판, 1급, 15*1220*2440mm | D9: M2 | W9: 자재 5
A10: 558E22F6D24E09A5E3A5823BD3E3DF31B6FEC7C2 | B10: T15 목모흡음보드 | C10: T15, 국내산 | D10: M2 | W10: 자재 6
A11: 558E22F6D24E09A5E3A5823BD3E3DF31B6FEC7C3 | B11: 차은시트 | C11: 2T | D11: M2 | W11: 자재 7
A12: 558E22F6D200591750453D3483ACAFEABC9FBD43 | B12: 디지털 도어록 | C12: 레바일체형 철재문용 | D12: 개소 | W12: 자재 8
A13: 558E22F6D200591750453D3483ACAFEABC9FBD40 | B13: 디지털 도어록 | C13: 레바일체형 목재문용 | D13: 개소 | W13: 자재 9
A14: 558E22F6D2F8D917C4EAFF3CD364D6C4553658 | B14: 철강설 | C14: 철강설, 고철, 작업설부산물 | D14: TON | W14: 자재 10 | X14: 수집상차도
A15: 558E22F6D2F8D917C4EAFF3CD364D6C455365B | B15: 철강설 | C15: 철강설, 고철, 작업설부산물 | D15: kg | W15: 자재 11 | X15: 수집상차도
A16: 558E22F6D2F8D917C4EAFF3CD364D6C455377E | B16: 철강설 | C16: 철강설, 스텐레스, 작업설부산물 | D16: kg | W16: 자재 12 | X16: 수집상차도
A17: 558E12D646B949A33667F33393D6790B39E66D | B17: 아르곤가스 | C17: 아르곤가스, 건설용알곤가스 | D17: L | W17: 자재 13
A18: 558E12D6469EC95917270C37739FD08DB0D7D8 | B18: 침투성방수제 | C18: 침투성방수제, 급결방수액 | D18: L | W18: 자재 14
A19: 558E12D6469EC95917239132F3FC139EBC440C | B19: 아스팔트방수재 | C19: 수용성 고무화아스팔트 AP-300 | D19: KG | W19: 자재 15
A20: 558E12D6469EC95917239132F3FC139EBC440F | B20: 아스팔트방수재 | C20: 수용성 아스팔트 프라이머 AP-100 | D20: KG | W20: 자재 16
A21: 558E12D6469EC95917239132F3FC139EBC440E | B21: 아스팔트방수재 | C21: 보강포 | D21: KG | W21: 자재 17
A22: 558E62566A9D390C7355633E03BE07898F72E2 | B22: 경유 | C22: 경유, 저유황 | D22: L | W22: 자재 18
A23: 55BBB2D6EA7309A0AD36DC353352918510535E | B23: 용접봉(연강용) | C23: 3.2(KSE5016) | D23: kg | W23: 자재 19
A24: 55BBB2D6EA7309A0AD36DC35335291851202DC | B24: 스테인리스강용알곤용접봉 | C24: 스테인리스강용알곤용접봉, ∮3.2mm, T-308 | D24: kg | W24: 자재 20
A25: 55A91276F31329C56A43913AB39CD4B05C0C5D | B25: 일반구조용압연강판 | C25: 일반구조용압연강판, 1.6mm | D25: kg | W25: 자재 21
A26: 55A91276F31329C56A43913AB39CD4B05C0C5A | B26: 일반구조용압연강판 | C26: 일반구조용압연강판, 2.3mm | D26: kg | W26: 자재 22
A27: 55A91276F31329C56A428F33B303261D0F0038 | B27: 스테인리스강판 | C27: 스테인리스강판, STS304, 1.5mm | D27: kg | W27: 자재 23
A28: 55A91276F31339E891023A3743E44F71C56F8D | B28: 각재 | C28: 각재, 외송 | D28: M3 | W28: 자재 24
... A63: 55A91276F375999B0A7E4E382333117A311D42 | B63: 나사 | C63: SCREW | D63: EA | W63: 자재 59
A64: 55A91276F375999B0A7E4E382333117A311D43 | B64: HILTI PIN | D64: EA | W64: 자재 60
A65: 55A91276F375999B0A7E4E382336EF9E04C7AD | B65: 경량철골천장틀 | C65: 경량철골천장틀, 몰딩(알루미늄), ㄷ형, 15*30*15*1.0mm | D65: M | W65: 자재 61
A66: 55A91276F375999A638DAE36539C63839409D87C | B66: 전기온돌판넬 | C66: 15T*1700*850 | D66: EA | W66: 자재 62
A67: 55A91276F375999A638DAE36539C63839409D87F | B67: 전기온돌판넬 | C67: 15T*1700*425 | D67: EA | W67: 자재 63
A68: 55A91276F375999A638DAE36539C63839409D87E | B68: 전기온돌판넬 | C68: 15T*850*425 | D68: EA | W68: 자재 64
A69: 55A91276F375999A638DAE36539C63839409D879 | B69: 보조블록 | C69: 15T*212.5*425 | D69: EA | W69: 자재 65
A70: 55A91276F375999A638DAE36539C63839409D878 | B70: 온도조절기 | C70: 소형 | D70: EA | W70: 자재 66
A71: 55A91276F375999A6388283F033E1C22582354 | B71: 비닐타일 | C71: 비닐타일, 3*450*450mm, 데코타일 | D71: M2 | W71: 자재 67
A72: 55A91276F375999A6388283F033E1C27D2E997 | B72: 비닐시트 | C72: 비닐시트, 2.0mm, 모노륨 | D72: M2 | W72: 자재 68 | X72: LG 명품기준
A73: 55A91276F375999A6388283F033B46917C724F | B73: 비닐시트 | C73: 비닐시트, 6.0mm, 고탄성비닐시트, EQ-Floor | D73: M2 | W73: 자재 69
A74: 55A91276F3759994DA426137D3EF1C7007C8CA | B74: 후드캡 | C74: 원형루버, 스테인리스 | D74: 개 | W74: 자재 70
...

Sheet  공사설정 
A1: 이 Sheet는 수정하지 마십시요
A2: 공사구분 | B2: A | C2: 타이틀
A3: 확정내역 | B3: 원내역
A4: 자재단가적용 | B4: 5
A5: 경비단가적용 | B5: 5
A6: 품목코드형식 | B6: XXXX-XXXXXXXXXXXXX
A7: 내역금액소수점처리 | B7: C | C7: 1
A8: 일위대가내역소수점처리 | B8: C | C8: 2
A9: 단가명 | B9: 조달청가격 | C9: 거래가격 | D9: 유통물가 | E9: 조사가격1 | F9: 조사가격2 | G9: TTTTT
A10: 환율 | B10: 0 | C10: 0 | D10: 0
A11: 시간당작업량 | B11: R | C11: 3
A12: 1회 사이클시간 | B12: R | C12: 3
A13: 시간당 작업사이클 | B13: R | C13: 2
A14: 일반변수 | B14: C | C14: 5
A15: 시간당 노임산출 계수 | B15: A | C15: 1/8*16/12*25/20 | D15: 1/8*16/12*25/20 | E15: 1/8*16/12*25/20 | F15: 1
A16: 재료비 할증 계수 | B16: 0 | C16: 0
A17: 노무비 할증 계수 | B17: 0 | C17: 0 | D17: 0 | E17: 0 | F17: 0 | G17: 0 | H17: 0 | I17: 0 | J17: 0 | K17: 0 | L17: 0 | M17: 0
A18: 경비 할증 계수 | B18: 0 | C18: 0
A19: 내역,일위대가 품명,규격,단위 따로적용
A20: 내역단가 소수점처리 | C20: 1
A21: 코드 | B21: 공종구분명 | C21: 원가비목코드
A22: 1 | B22: 작 업 부 산 물 | C22: A3
A23: 2 | B23: 운 반 비 | C23: C1
A24: 3 | B24: 관 급 자 재 비 | C24: DJ
A25: 4 | B25: 사 급 자 재 비 | C25: D3
A26: 5 | B26: 외 자 재
A27: 6 | B27: 폐기물처리비 | C27: D4
A28: 7 | B28: ...
A29: 8 | B29: ...
A30: 9 | B30: ...

Sheet Sheet1
